Workbook
Name Ersatzspalten: 'Preisblatt | opt. Leistung'!$I$3:$L$3
Name Ersatzspalten: 'Preisblatt | Leistung'!$I$3:$L$3
Name Erstattungsart: Listen!$B$4:$B$7
Name JaNein: [1]Listen!$D$4:$D$5
Name lSFK: '[2]Liste der Schlüsselfachkräfte'!$B$11:$B$34
Name lSFK: 'Liste der Schlüsselfachkräfte'!$B$11:$B$34
Name rZeilen: 'Preisblatt | opt. Leistung'!$N$13:$N$19
Name rZeilen: 'Preisblatt | Leistung'!$N$13:$N$19
Name VENr: 'Preisblatt | opt. Leistung'!#REF!
Name VENr: 'Preisblatt | Leistung'!#REF!
Name VEspalten: 'Preisblatt | opt. Leistung'!#REF!
Name VEspalten: 'Preisblatt | Leistung'!#REF!

Sheet Preisblatt | Leistung
A1: Preisblatt - Leistung
A3: Vertragsnummer (VN): | B3: 81311588 | C3: Datum:
A5: Projektnummer/ Kostenstellennummer: | B5: 15590 | C5: Auftragnehmer (AN):
C7: Adresse:
A9: 1. Festpreise
A11: Position | B11: Beschreibung | D11: Menge | E11: Vergütung | F11: Summe | G11: Erläuterungen
A12: Gesamtsumme | F12: =D12*E12 -> 0
A13: Milestone 1 | F13: =D13*E13 -> 0
A14: Milestone 2 | F14: =D14*E14 -> 0
A15: Milestone 3 | F15: =D15*E15 -> 0
A16: Milestone 4 | F16: =D16*E16 -> 0
A17: Milestone 5 | F17: =D17*E17 -> 0
A18: Milestone 6 | F18: =D18*E18 -> 0
A19: Milestone 7 | F19: =D19*E19 -> 0
A21: Zwischensumme | F21: =SUM(F12:F20) -> 0
A23: 2. Honorare und sonstige auftragsbedingte Kosten
A25: 2.1 Honorar Tagessatz Position | B25: Name | C25: Erstattungsart | D25: Menge FKT | E25: Vergütung | F25: Summe | G25: Erläuterungen
A26: Teamleiter | B26: =IFERROR(VLOOKUP(A26,'Liste der Schlüsselfachkräfte'!$B$11:$D$34,3,0)&" "&VLOOKUP(A26,'Liste der Schlüsselfachkräfte'!$B$11:$D$34,2,0),"N.N.") | C26: Pauschal / Menge | D26: 18 | F26: =D26*E26 -> 0
A27: SFK 1 | B27: =IFERROR(VLOOKUP(A27,'Liste der Schlüsselfachkräfte'!$B$11:$D$34,3,0)&" "&VLOOKUP(A27,'Liste der Schlüsselfachkräfte'!$B$11:$D$34,2,0),"N.N.") | C27: Pauschal / Menge | F27: =D27*E27 -> 0
A28: SFK 2 | B28: =IFERROR(VLOOKUP(A28,'Liste der Schlüsselfachkräfte'!$B$11:$D$34,3,0)&" "&VLOOKUP(A28,'Liste der Schlüsselfachkräfte'!$B$11:$D$34,2,0),"N.N.") | C28: Pauschal / Menge | F28: =D28*E28 -> 0
A29: SFK 3 | B29: =IFERROR(VLOOKUP(A29,'Liste der Schlüsselfachkräfte'!$B$11:$D$34,3,0)&" "&VLOOKUP(A29,'Liste der Schlüsselfachkräfte'!$B$11:$D$34,2,0),"N.N.") | C29: Pauschal / Menge | F29: =D29*E29 -> 0
A30: SFK 4 | B30: =IFERROR(VLOOKUP(A30,'Liste der Schlüsselfachkräfte'!$B$11:$D$34,3,0)&" "&VLOOKUP(A30,'Liste der Schlüsselfachkräfte'!$B$11:$D$34,2,0),"N.N.") | C30: Pauschal / Menge | F30: =D30*E30 -> 0
A31: SFK 5 | B31: =IFERROR(VLOOKUP(A31,'Liste der Schlüsselfachkräfte'!$B$11:$D$34,3,0)&" "&VLOOKUP(A31,'Liste der Schlüsselfachkräfte'!$B$11:$D$34,2,0),"N.N.") | C31: Pauschal / Menge | F31: =D31*E31 -> 0
A32: Fachkräftepool 1 | B32: =IFERROR(VLOOKUP(A32,'Liste der Schlüsselfachkräfte'!$B$11:$D$34,3,0)&" "&VLOOKUP(A32,'Liste der Schlüsselfachkräfte'!$B$11:$D$34,2,0),"N.N.") -> N.N. | C32: Pauschal / Menge | D32: 36 | F32: =D32*E32 -> 0
A33: Fachkräftepool 2 | B33: =IFERROR(VLOOKUP(A33,'Liste der Schlüsselfachkräfte'!$B$11:$D$34,3,0)&" "&VLOOKUP(A33,'Liste der Schlüsselfachkräfte'!$B$11:$D$34,2,0),"N.N.") -> N.N. | C33: Pauschal / Menge | F33: =D33*E33 -> 0
A34: Fachkräftepool 3 | B34: =IFERROR(VLOOKUP(A34,'Liste der Schlüsselfachkräfte'!$B$11:$D$34,3,0)&" "&VLOOKUP(A34,'Liste der Schlüsselfachkräfte'!$B$11:$D$34,2,0),"N.N.") -> N.N. | C34: Pauschal / Menge | F34: =D34*E34 -> 0
A35: Fachkräftepool 4 | B35: =IFERROR(VLOOKUP(A35,'Liste der Schlüsselfachkräfte'!$B$11:$D$34,3,0)&" "&VLOOKUP(A35,'Liste der Schlüsselfachkräfte'!$B$11:$D$34,2,0),"N.N.") -> N.N. | C35: Pauschal / Menge | F35: =D35*E35 -> 0
A36: Fachkräftepool 5 | B36: =IFERROR(VLOOKUP(A36,'Liste der Schlüsselfachkräfte'!$B$11:$D$34,3,0)&" "&VLOOKUP(A36,'Liste der Schlüsselfachkräfte'!$B$11:$D$34,2,0),"N.N.") -> N.N. | C36: Pauschal / Menge | F36: =D36*E36 -> 0
A38: Zwischensumme | F38: =SUM(F26:F37) -> 0
A40: 2.2 Auftragsbed. Kosten Position | B40: Name | C40: Abrechnungs-schlüssel | D40: Menge | E40: Preis | F40: Summe | G40: Erläuterungen
A41: Teamleiter | B41: =IFERROR(VLOOKUP(A41,'Liste der Schlüsselfachkräfte'!$B$11:$D$34,3,0)&" "&VLOOKUP(A41,'Liste der Schlüsselfachkräfte'!$B$11:$D$34,2,0),"N.N.") | C41: Pauschal / Menge | F41: =D41*E41 -> 0
A42: SFK 1 | B42: =IFERROR(VLOOKUP(A42,'Liste der Schlüsselfachkräfte'!$B$11:$D$34,3,0)&" "&VLOOKUP(A42,'Liste der Schlüsselfachkräfte'!$B$11:$D$34,2,0),"N.N.") | C42: Pauschal / Menge | F42: =D42*E42 -> 0
A43: SFK 2 | B43: =IFERROR(VLOOKUP(A43,'Liste der Schlüsselfachkräfte'!$B$11:$D$34,3,0)&" "&VLOOKUP(A43,'Liste der Schlüsselfachkräfte'!$B$11:$D$34,2,0),"N.N.") | C43: Pauschal / Menge | F43: =D43*E43 -> 0
A44: SFK 3 | B44: =IFERROR(VLOOKUP(A44,'Liste der Schlüsselfachkräfte'!$B$11:$D$34,3,0)&" "&VLOOKUP(A44,'Liste der Schlüsselfachkräfte'!$B$11:$D$34,2,0),"N.N.") | C44: Pauschal / Menge | F44: =D44*E44 -> 0
A45: SFK 4 | B45: =IFERROR(VLOOKUP(A45,'Liste der Schlüsselfachkräfte'!$B$11:$D$34,3,0)&" "&VLOOKUP(A45,'Liste der Schlüsselfachkräfte'!$B$11:$D$34,2,0),"N.N.") | C45: Pauschal / Menge | F45: =D45*E45 -> 0
A46: SFK 5 | B46: =IFERROR(VLOOKUP(A46,'Liste der Schlüsselfachkräfte'!$B$11:$D$34,3,0)&" "&VLOOKUP(A46,'Liste der Schlüsselfachkräfte'!$B$11:$D$34,2,0),"N.N.") | C46: Pauschal / Menge | F46: =D46*E46 -> 0
A47: Fachkräftepool 1 | B47: =IFERROR(VLOOKUP(A47,'Liste der Schlüsselfachkräfte'!$B$11:$D$34,3,0)&" "&VLOOKUP(A47,'Liste der Schlüsselfachkräfte'!$B$11:$D$34,2,0),"N.N.") -> N.N. | C47: Pauschal / Menge | F47: =D47*E47 -> 0
A48: Fachkräftepool 2 | B48: =IFERROR(VLOOKUP(A48,'Liste der Schlüsselfachkräfte'!$B$11:$D$34,3,0)&" "&VLOOKUP(A48,'Liste der Schlüsselfachkräfte'!$B$11:$D$34,2,0),"N.N.") -> N.N. | C48: Pauschal / Menge | F48: =D48*E48 -> 0
A49: Fachkräftepool 3 | B49: =IFERROR(VLOOKUP(A49,'Liste der Schlüsselfachkräfte'!$B$11:$D$34,3,0)&" "&VLOOKUP(A49,'Liste der Schlüsselfachkräfte'!$B$11:$D$34,2,0),"N.N.") -> N.N. | C49: Pauschal / Menge | F49: =D49*E49 -> 0
A50: Fachkräftepool 4 | B50: =IFERROR(VLOOKUP(A50,'Liste der Schlüsselfachkräfte'!$B$11:$D$34,3,0)&" "&VLOOKUP(A50,'Liste der Schlüsselfachkräfte'!$B$11:$D$34,2,0),"N.N.") -> N.N. | C50: Pauschal / Menge | F50: =D50*E50 -> 0
...

Sheet Preisblatt | opt. Leistung
A1: Preisblatt | Option
A3: Vertragsnummer (VN): | B3: ='Preisblatt | Leistung'!B3 -> 81311588 | C3: Datum: | D3: ='Preisblatt | Leistung'!D3 -> 0
A5: Projektnummer/ Kostenstellennummer: | B5: ='Preisblatt | Leistung'!B5 -> 15590 | C5: Auftragnehmer (AN): | D5: ='Preisblatt | Leistung'!D5 -> 0
C7: Adresse: | D7: ='Preisblatt | Leistung'!D7 -> 0
A9: 1. Festpreise
A11: Position | B11: Beschreibung | D11: Menge | E11: Vergütung | F11: Summe | G11: Erläuterungen
A12: Gesamtsumme | F12: =D12*E12 -> 0
A13: Milestone 1 | F13: =D13*E13 -> 0
A14: Milestone 2 | F14: =D14*E14 -> 0
A15: Milestone 3 | F15: =D15*E15 -> 0
A16: Milestone 4 | F16: =D16*E16 -> 0
A17: Milestone 5 | F17: =D17*E17 -> 0
A18: Milestone 6 | F18: =D18*E18 -> 0
A19: Milestone 7 | F19: =D19*E19 -> 0
A21: Zwischensumme | F21: =SUM(F12:F20) -> 0
A23: 2. Honorare und sonstige auftragsbedingte Kosten
A25: 2.1 Honorar Tagessatz Position | B25: Name | C25: Erstattungsart | D25: Menge FKT | E25: Vergütung | F25: Summe | G25: Erläuterungen
A26: Teamleiter | B26: =IFERROR(VLOOKUP(A26,'Liste der Schlüsselfachkräfte'!$B$11:$D$34,3,0)&" "&VLOOKUP(A26,'Liste der Schlüsselfachkräfte'!$B$11:$D$34,2,0),"N.N.") | C26: Pauschal / Menge | F26: =D26*E26 -> 0
A27: SFK 1 | B27: =IFERROR(VLOOKUP(A27,'Liste der Schlüsselfachkräfte'!$B$11:$D$34,3,0)&" "&VLOOKUP(A27,'Liste der Schlüsselfachkräfte'!$B$11:$D$34,2,0),"N.N.") | C27: Pauschal / Menge | F27: =D27*E27 -> 0
A28: SFK 2 | B28: =IFERROR(VLOOKUP(A28,'Liste der Schlüsselfachkräfte'!$B$11:$D$34,3,0)&" "&VLOOKUP(A28,'Liste der Schlüsselfachkräfte'!$B$11:$D$34,2,0),"N.N.") | C28: Pauschal / Menge | F28: =D28*E28 -> 0
A29: SFK 3 | B29: =IFERROR(VLOOKUP(A29,'Liste der Schlüsselfachkräfte'!$B$11:$D$34,3,0)&" "&VLOOKUP(A29,'Liste der Schlüsselfachkräfte'!$B$11:$D$34,2,0),"N.N.") | C29: Pauschal / Menge | F29: =D29*E29 -> 0
A30: SFK 4 | B30: =IFERROR(VLOOKUP(A30,'Liste der Schlüsselfachkräfte'!$B$11:$D$34,3,0)&" "&VLOOKUP(A30,'Liste der Schlüsselfachkräfte'!$B$11:$D$34,2,0),"N.N.") | C30: Pauschal / Menge | F30: =D30*E30 -> 0
A31: SFK 5 | B31: =IFERROR(VLOOKUP(A31,'Liste der Schlüsselfachkräfte'!$B$11:$D$34,3,0)&" "&VLOOKUP(A31,'Liste der Schlüsselfachkräfte'!$B$11:$D$34,2,0),"N.N.") | C31: Pauschal / Menge | F31: =D31*E31 -> 0
A32: Fachkräftepool 1 | B32: =IFERROR(VLOOKUP(A32,'Liste der Schlüsselfachkräfte'!$B$11:$D$34,3,0)&" "&VLOOKUP(A32,'Liste der Schlüsselfachkräfte'!$B$11:$D$34,2,0),"N.N.") -> N.N. | C32: Pauschal / Menge | F32: =D32*E32 -> 0
A33: Fachkräftepool 2 | B33: =IFERROR(VLOOKUP(A33,'Liste der Schlüsselfachkräfte'!$B$11:$D$34,3,0)&" "&VLOOKUP(A33,'Liste der Schlüsselfachkräfte'!$B$11:$D$34,2,0),"N.N.") -> N.N. | C33: Pauschal / Menge | F33: =D33*E33 -> 0
A34: Fachkräftepool 3 | B34: =IFERROR(VLOOKUP(A34,'Liste der Schlüsselfachkräfte'!$B$11:$D$34,3,0)&" "&VLOOKUP(A34,'Liste der Schlüsselfachkräfte'!$B$11:$D$34,2,0),"N.N.") -> N.N. | C34: Pauschal / Menge | F34: =D34*E34 -> 0
A35: Fachkräftepool 4 | B35: =IFERROR(VLOOKUP(A35,'Liste der Schlüsselfachkräfte'!$B$11:$D$34,3,0)&" "&VLOOKUP(A35,'Liste der Schlüsselfachkräfte'!$B$11:$D$34,2,0),"N.N.") -> N.N. | C35: Pauschal / Menge | F35: =D35*E35 -> 0
A36: Fachkräftepool 5 | B36: =IFERROR(VLOOKUP(A36,'Liste der Schlüsselfachkräfte'!$B$11:$D$34,3,0)&" "&VLOOKUP(A36,'Liste der Schlüsselfachkräfte'!$B$11:$D$34,2,0),"N.N.") -> N.N. | C36: Pauschal / Menge | F36: =D36*E36 -> 0
A38: Zwischensumme | F38: =SUM(F26:F37) -> 0
A40: 2.2 Auftragsbed. Kosten Position | B40: Name | C40: Abrechnungs-schlüssel | D40: Menge | E40: Preis | F40: Summe | G40: Erläuterungen
A41: Teamleiter | B41: =IFERROR(VLOOKUP(A41,'Liste der Schlüsselfachkräfte'!$B$11:$D$34,3,0)&" "&VLOOKUP(A41,'Liste der Schlüsselfachkräfte'!$B$11:$D$34,2,0),"N.N.") | C41: Pauschal / Menge | F41: =D41*E41 -> 0
A42: SFK 1 | B42: =IFERROR(VLOOKUP(A42,'Liste der Schlüsselfachkräfte'!$B$11:$D$34,3,0)&" "&VLOOKUP(A42,'Liste der Schlüsselfachkräfte'!$B$11:$D$34,2,0),"N.N.") | C42: Pauschal / Menge | F42: =D42*E42 -> 0
A43: SFK 2 | B43: =IFERROR(VLOOKUP(A43,'Liste der Schlüsselfachkräfte'!$B$11:$D$34,3,0)&" "&VLOOKUP(A43,'Liste der Schlüsselfachkräfte'!$B$11:$D$34,2,0),"N.N.") | C43: Pauschal / Menge | F43: =D43*E43 -> 0
A44: SFK 3 | B44: =IFERROR(VLOOKUP(A44,'Liste der Schlüsselfachkräfte'!$B$11:$D$34,3,0)&" "&VLOOKUP(A44,'Liste der Schlüsselfachkräfte'!$B$11:$D$34,2,0),"N.N.") | C44: Pauschal / Menge | F44: =D44*E44 -> 0
A45: SFK 4 | B45: =IFERROR(VLOOKUP(A45,'Liste der Schlüsselfachkräfte'!$B$11:$D$34,3,0)&" "&VLOOKUP(A45,'Liste der Schlüsselfachkräfte'!$B$11:$D$34,2,0),"N.N.") | C45: Pauschal / Menge | F45: =D45*E45 -> 0
A46: SFK 5 | B46: =IFERROR(VLOOKUP(A46,'Liste der Schlüsselfachkräfte'!$B$11:$D$34,3,0)&" "&VLOOKUP(A46,'Liste der Schlüsselfachkräfte'!$B$11:$D$34,2,0),"N.N.") | C46: Pauschal / Menge | F46: =D46*E46 -> 0
A47: Fachkräftepool 1 | B47: =IFERROR(VLOOKUP(A47,'Liste der Schlüsselfachkräfte'!$B$11:$D$34,3,0)&" "&VLOOKUP(A47,'Liste der Schlüsselfachkräfte'!$B$11:$D$34,2,0),"N.N.") -> N.N. | C47: Pauschal / Menge | F47: =D47*E47 -> 0
A48: Fachkräftepool 2 | B48: =IFERROR(VLOOKUP(A48,'Liste der Schlüsselfachkräfte'!$B$11:$D$34,3,0)&" "&VLOOKUP(A48,'Liste der Schlüsselfachkräfte'!$B$11:$D$34,2,0),"N.N.") -> N.N. | C48: Pauschal / Menge | F48: =D48*E48 -> 0
A49: Fachkräftepool 3 | B49: =IFERROR(VLOOKUP(A49,'Liste der Schlüsselfachkräfte'!$B$11:$D$34,3,0)&" "&VLOOKUP(A49,'Liste der Schlüsselfachkräfte'!$B$11:$D$34,2,0),"N.N.") -> N.N. | C49: Pauschal / Menge | F49: =D49*E49 -> 0
A50: Fachkräftepool 4 | B50: =IFERROR(VLOOKUP(A50,'Liste der Schlüsselfachkräfte'!$B$11:$D$34,3,0)&" "&VLOOKUP(A50,'Liste der Schlüsselfachkräfte'!$B$11:$D$34,2,0),"N.N.") -> N.N. | C50: Pauschal / Menge | F50: =D50*E50 -> 0
...

Sheet Summe Leistung + opt. Leist.
A1: Preisblatt - Summe Leistung + Option
A3: Vertragsnummer (VN): | B3: ='Preisblatt | Leistung'!B3 -> 81311588 | C3: Datum: | D3: ='Preisblatt | Leistung'!D3 -> 0
A5: Projektnummer (PN): | B5: ='Preisblatt | Leistung'!B5 -> 15590 | C5: Auftragnehmer (AN): | D5: ='Preisblatt | Leistung'!D5 -> 0
C7: Adresse: | D7: ='Preisblatt | Leistung'!D7 -> 0
A9: 1. Festpreise
A11: Zwischensumme | E11: ='Preisblatt | Leistung'!F21+'Preisblatt | opt. Leistung'!F21 -> 0
A13: 2. Honorare und sonstige auftragsbedingte Kosten
A15: 2.1 Honorar Tagessatz
A16: Zwischensumme | E16: ='Preisblatt | Leistung'!F38+'Preisblatt | opt. Leistung'!F38 -> 0
A18: 2.2 Auftragsbed. Kosten
A19: Zwischensumme | E19: ='Preisblatt | Leistung'!F53+'Preisblatt | opt. Leistung'!F53 -> 0
A21: 3. Reisekosten
A22: Link auf die aktuelle Ländertabelle des Bundes:
A23: https://www.bundesfinanzministerium.de/Content/DE/Downloads/BMF_Schreiben/Steuerarten/Lohnsteuer/2023-11-21-steuerliche-behandlung-reisekosten-reisekostenverguetungen-2024.html
A25: Zwischensumme | E25: ='Preisblatt | Leistung'!F75+'Preisblatt | opt. Leistung'!F75 -> 22518
A27: 4. Andere Kosten
A29: Zwischensumme | E29: ='Preisblatt | Leistung'!F94+'Preisblatt | opt. Leistung'!F94 -> 6500
A31: 5. Gesamtkosten
A33: Gesamtsumme (netto) | E33: ='Preisblatt | Leistung'!F98+'Preisblatt | opt. Leistung'!F98 -> 29018

Sheet Liste der Schlüsselfachkräfte
B2: Liste der Schlüsselfachkräfte (SFK)
B3: * Nur Fachkräfte, für die Vertragsergänzung erforderlich ist
B4: ** Bei Wechsel der Schlüsselfachkraft bitte in Erläuterungen das Einsatzende eintragen und bei der neuen Fachkraft den Einsatzbeginn
B6: VN: | C6: =IF('Preisblatt | Leistung'!B3="","",'Preisblatt | Leistung'!B3) -> 81311588 | E6: Datum: | F6: ='Preisblatt | Leistung'!D3 -> 0
B8: PN: | C8: =IF('Preisblatt | Leistung'!B5="","",'Preisblatt | Leistung'!B5) -> 15590
B10: Bezeichnung Preisblatt | C10: Name | D10: Vorname | E10: Geburtsdatum | F10: Wohnort | G10: Erläuterung für Vertragsergänzungen
B11: Teamleiter
B12: SFK 1
B13: SFK 2
B14: SFK 3
B15: SFK 4
B16: SFK 5
B17: SFK 6

Sheet Listen
B3: Erstattungsart
B4: Bitte wählen
B5: Pauschal / Menge
B6: gegen Nachweis
B7: entfällt
