Workbook
Name _Toc413163689: Deckblatt!#REF!
Name Bereich_1: IZDM!$E$5:$E$404
Name Grundfläche: IZDM!$G$5:$G$404
Name Grundfläche_AOZ: #REF!
Name Grundfläche_AOZ: #REF!
Name Grundfläche_SHK: #REF!
Name Grundfläche_SHK: #REF!
Name Grundfläche_WH: #REF!
Name Grundfläche_WH: #REF!
Name Monatsfläche_AOZ_GESAMT: #REF!
Name Monatsfläche_AOZ_GESAMT: #REF!
Name Monatsfläche_AOZ_Werktag: #REF!
Name Monatsfläche_AOZ_Werktag: #REF!
Name Monatsfläche_SHK_GESAMT: #REF!
Name Monatsfläche_SHK_GESAMT: #REF!
Name Monatsfläche_SHK_Sonntag: #REF!
Name Monatsfläche_SHK_Sonntag: #REF!
Name Monatsfläche_SHK_Werktag: #REF!
Name Monatsfläche_SHK_Werktag: #REF!
Name Monatsfläche_VEH_Gesamt: IZDM!$Z$5:$Z$404
Name Monatsfläche_VEH_Sonntag: IZDM!$U$5:$U$404
Name Monatsfläche_VEH_Werktag: IZDM!$O$5:$O$404
Name Monatsfläche_WH_GESAMT: #REF!
Name Monatsfläche_WH_GESAMT: #REF!
Name Monatsfläche_WH_Werktag: #REF!
Name Monatsfläche_WH_Werktag: #REF!
Name Monatspreis_AOZ_GESAMT: #REF!
Name Monatspreis_AOZ_GESAMT: #REF!
Name Monatspreis_AOZ_Werktag: #REF!
Name Monatspreis_AOZ_Werktag: #REF!
Name Monatspreis_SHK_GESAMT: #REF!
Name Monatspreis_SHK_GESAMT: #REF!
Name Monatspreis_SHK_Sonntag: #REF!
Name Monatspreis_SHK_Sonntag: #REF!
Name Monatspreis_SHK_Werktag: #REF!
Name Monatspreis_SHK_Werktag: #REF!
Name Monatspreis_VEH_Gesamt: IZDM!$AB$5:$AB$404
Name Monatspreis_VEH_Sonntag: IZDM!$Y$5:$Y$404
Name Monatspreis_VEH_Werktags: IZDM!$S$5:$S$404
Name Monatspreis_WH_GESAMT: #REF!
Name Monatspreis_WH_GESAMT: #REF!
Name Monatspreis_WH_Werktag: #REF!
Name Monatspreis_WH_Werktag: #REF!
Name Monatsstunden_AOZ_GESAMT: #REF!
Name Monatsstunden_AOZ_GESAMT: #REF!
Name Monatsstunden_AOZ_Werktag: #REF!
Name Monatsstunden_AOZ_Werktag: #REF!
Name Monatsstunden_SHK_GESAMT: #REF!
Name Monatsstunden_SHK_GESAMT: #REF!
Name Monatsstunden_SHK_Sonntag: #REF!
Name Monatsstunden_SHK_Sonntag: #REF!
Name Monatsstunden_SHK_Werktag: #REF!
Name Monatsstunden_SHK_Werktag: #REF!
Name Monatsstunden_Sonntag: IZDM!$X$5:$X$404
Name Monatsstunden_VEH_GESAMT: IZDM!$AA$5:$AA$404
Name Monatsstunden_VEH_Werktag: IZDM!$R$5:$R$404
Name Monatsstunden_WH_GESAMT: #REF!
Name Monatsstunden_WH_GESAMT: #REF!
Name Monatsstunden_WH_Werktag: #REF!
Name Monatsstunden_WH_Werktag: #REF!

Sheet Deckblatt
A1: Anlage 1 Angebotspreis V2
A2: Vergabeunterlagen zur Ausschreibung: Ausschreibung zur Vergabe der Unterhaltsreinigung des Gebäudes "Innovationszentrum Digitale Medizin + Bildungsakademie (IZDM)" für das Universitätsklinikum Aachen -Anstalt des öffentlichen Rechts
A4: Unter den nachfolgenden Reitern finden Sie die auszufüllenden preisrelevanten Anlagen für die Ausschreibung zur Vergabe der Unterhaltsreinigung für das Universitätsklinikum Aachen.
A6: Allgemeine Informationen des Anbieters
A8: Bitte füllen Sie die nachfolgenden Felder aus.
A10: Firma
A12: Ansprechpartner
A14: Anschrift
A16: Email
A18: Telefon
A20: Angebotsdatum
A100: UKA2024

Sheet Angebotszusammenstellung
B1: Angebotszusammenstellung
B2: Übersicht Unterhaltsreinigung
B4: Objekt / Bereich | D4: Montag - Samstag | E4: Bemerkungen | F4: Netto ab 01.10.2025 | G4: Brutto ab 01.10.2025
B6: 1 | C6: Unterhaltsreinigung
B7: 1.1 | C7: =IZDM!A1 -> Raumbuch inkl. Kalkulation "Gebäude IZDM" Stand 10.04.2025 | D7: =CONCATENATE("Monatsfläche ",ROUND(IZDM!Z4,2)," m²") -> Monatsfläche 122075,38 m² | E7: ohne Feiertage | F7: =IZDM!AB4 -> #DIV/0! | G7: =F7*1.19 -> #DIV/0!
B8: 1.2 | C8: Transportzeiten für Feuchtwischbezüge 2 x wöchentlich | D8: =0.5*'R_Häufigkeit_Faktoren UHR'!H5 -> 4.3452381 | E8: ohne Feiertage | F8: 0 | G8: =F8*1.19 -> 0
B9: 2 | C9: Vorarbeiter/-In
B10: 2.1 | C10: Vorarbeiter/-In | D10: 2 | E10: Pauschaler Betrag für die Vorarbeiter/-In | F10: 0 | G10: =F10*1.19 -> 0
C11: Summe Unterhaltsreinigung pro Monat | F11: =SUM(F7:F10) -> #DIV/0! | G11: =SUM(G7:G10) -> #DIV/0!
C12: Summe Unterhaltsreinigung pro Jahr | F12: =F11*12 -> #DIV/0! | G12: =G11*12 -> #DIV/0!
C13: Gesamtvergabevolumen (Lfz. 5 Jahre; 3 + 2x Option) | F13: =F12*5 -> #DIV/0! | G13: =G12*5 -> #DIV/0!
B15: bearbeitbare Felder
B18: Übersicht Stundenverrechnungssätze | F18: Montag - Samstag
F19: Netto | G19: Brutto
B20: 3 | C20: Stundenverrechnungssatz für Einzelbeauftragungen: | F20: 0 | G20: =F20*1.19 -> 0
C24: =Deckblatt!$B$20 -> 0
C26: Datum

Sheet UKA_Aussengebäude_Übersicht
B2: Übersicht der Einzelraumbücher
F3: Werktag | I3: Sonntag | L3: GESAMT
B4: Los 1 | D4: Fläche Gesamt [m²] | E4: Vergabe-fläche [m²] | F4: Monatsfläche [m²] | G4: Monatsstunden [Std.] | H4: Preis/Monat [EUR] | I4: Monats-fläche [m²] | J4: Monats-stunden [Std.] | K4: Preis/Monat [EUR] | L4: Monatsfläche GESAMT [m²] | M4: Monats-stunden [Std.] | N4: Monats-preis [EUR] | O4: Leistungswert je m² | P4: Wert je m² | Q4: Wert je Std.
B6: UKA Aussengebäude | C6: GESAMT | D6: =SUM(D7:D13) -> 12520.11 | E6: =SUM(E7:E13) -> 8439.71 | F6: =SUM(F7:F13) -> 121842.25 | G6: =SUM(G7:G13) -> #DIV/0! | H6: =SUM(H7:H13) -> #DIV/0! | I6: =SUM(I7:I13) -> 233.13333 | J6: =SUM(J7:J13) -> #DIV/0! | K6: =SUM(K7:K13) -> #DIV/0! | ... N6: =SUM(N7:N13) -> #DIV/0! | O6: =L6/M6 -> #DIV/0! | P6: =N6/L6 -> #DIV/0! | Q6: =N6/M6 -> #DIV/0!
C7: Gebäude 1 Lehr- und Weiterbildungsgebäude Bio-Medizintechnik | D7: =IZDM!G4 -> 12520.11 | E7: =IZDM!L4 -> 8439.71 | F7: =IZDM!O4 -> 121842.25 | G7: =IZDM!R4 -> #DIV/0! | H7: =IZDM!S4 -> #DIV/0! | I7: =IZDM!U4 -> 233.13333 | J7: =IZDM!X4 -> #DIV/0! | K7: =IZDM!Y4 -> #DIV/0! | L7: =IZDM!Z4 -> 122075.38 | M7: =IZDM!AA4 -> #DIV/0! | N7: =IZDM!AB4 -> #DIV/0! | O7: =L7/M7 -> #DIV/0! | P7: =N7/L7 -> #DIV/0! | Q7: =N7/M7 -> #DIV/0!
C15: =Deckblatt!$B$20 -> 0
C17: Datum | E17: =Deckblatt!$B$10 -> 0
E18: =Deckblatt!$B$12 -> 0

Sheet IZDM
A1: Raumbuch inkl. Kalkulation "Gebäude IZDM" Stand 10.04.2025
N2: Montag - Samstag | T2: Sonntags / Feiertags | Z2: GESAMT
A3: Lfd. Nr. | B3: Gebäude | C3: Etage | D3: Bereich | E3: Flur | F3: Raum-Nr. | G3: Fläche [m²] | H3: Bezeichnung | I3: Belag | J3: RG | K3: RA | L3: Vergabe-fläche | M3: TU | N3: Inter-vall | O3: Monats-fläche [m²] | P3: SVS [EUR] | Q3: Leistung [m²/Std.] | R3: Monats-stunden [Std.] | S3: Preis/Monat [EUR] | T3: Inter-vall | U3: Monats-fläche [m²] | V3: SVS [EUR] | W3: Leistung [m²/Std.] | X3: Monats-stunden [Std.] | Y3: Preis/Monat [EUR] | Z3: Monatsfläche Gesamt | AA3: Monats-stunden [Std.] | AB3: Monats-preis [EUR] | AC3: Bemerkung
G4: =SUBTOTAL(9,G5:G404) -> 12520.11 | L4: =SUBTOTAL(9,L5:L404) -> 8439.71 | O4: =SUBTOTAL(9,O5:O404) -> 121842.25 | R4: =SUBTOTAL(9,R5:R404) -> #DIV/0! | S4: =SUBTOTAL(9,S5:S404) -> #DIV/0! | U4: =SUBTOTAL(9,U5:U404) -> 233.13333 | X4: =SUBTOTAL(9,X5:X404) -> #DIV/0! | Y4: =SUBTOTAL(9,Y5:Y404) -> #DIV/0! | Z4: =SUBTOTAL(9,Z5:Z404) -> 122075.38 | AA4: =SUBTOTAL(9,AA5:AA404) -> #DIV/0! | AB4: =SUBTOTAL(9,AB5:AB404) -> #DIV/0! | AC4: =Z4/AA4 -> #DIV/0!
A5: 1 | B5: Untergeschoss | C5: -2 | D5: Alle | F5: 01 | G5: 69.6 | H5: Fahrräder | I5: Beschichtung | J5: K | K5: V | L5: =IF(K5="NV","",G5) -> 69.6 | M5: M1 | N5: =IF(K5="NV","",IF(VLOOKUP(M5,'R_Häufigkeit_Faktoren UHR'!$B$4:$I$24,7,FALSE)=0,"",VLOOKUP(M5,'R_Häufigkeit_Faktoren UHR'!$B$4:$I$24,7,FALSE))) -> 1 | O5: =IF(N5="","",N5*L5) -> 69.6 | Q5: =IF(N5="","",VLOOKUP(J5,Raumgruppen_Leistungswerte!$B$5:$F$35,5,FALSE)) -> 0 | R5: =IF(N5="","",L5/Q5*N5) -> #DIV/0! | S5: =IF(K5="NV","",R5*P5) -> #DIV/0! | T5: =IF(K5="NV","",IF(VLOOKUP(M5,'R_Häufigkeit_Faktoren UHR'!$B$4:$I$24,8,FALSE)=0,"",VLOOKUP(M5,'R_Häufigkeit_Faktoren UHR'!$B$4:$I$24,8,FALSE))) | U5: =IF(T5="","",T5*L5) | W5: =IF(T5="","",VLOOKUP(J5,Raumgruppen_Leistungswerte!$B$5:$F$35,5,FALSE)) | X5: =IF(T5="","",L5/W5*T5) | Y5: =IF(T5="","",X5*V5) | Z5: =IF(U5="",O5,O5+U5) -> 69.6 | AA5: =IF(X5="",R5,X5+R5) -> #DIV/0! | AB5: =IF(Y5="",S5,S5+Y5) -> #DIV/0!
A6: 2 | B6: Untergeschoss | C6: -2 | D6: Alle | F6: 02 | G6: 34.7 | H6: Lager | I6: Beschichtung | J6: I1 | K6: V | L6: =IF(K6="NV","",G6) -> 34.7 | M6: 1 | N6: =IF(K6="NV","",IF(VLOOKUP(M6,'R_Häufigkeit_Faktoren UHR'!$B$4:$I$24,7,FALSE)=0,"",VLOOKUP(M6,'R_Häufigkeit_Faktoren UHR'!$B$4:$I$24,7,FALSE))) -> 4.3452381 | O6: =IF(N6="","",N6*L6) -> 150.77976 | Q6: =IF(N6="","",VLOOKUP(J6,Raumgruppen_Leistungswerte!$B$5:$F$35,5,FALSE)) -> 0 | R6: =IF(N6="","",L6/Q6*N6) -> #DIV/0! | S6: =IF(K6="NV","",R6*P6) -> #DIV/0! | T6: =IF(K6="NV","",IF(VLOOKUP(M6,'R_Häufigkeit_Faktoren UHR'!$B$4:$I$24,8,FALSE)=0,"",VLOOKUP(M6,'R_Häufigkeit_Faktoren UHR'!$B$4:$I$24,8,FALSE))) | U6: =IF(T6="","",T6*L6) | W6: =IF(T6="","",VLOOKUP(J6,Raumgruppen_Leistungswerte!$B$5:$F$35,5,FALSE)) | X6: =IF(T6="","",L6/W6*T6) | Y6: =IF(T6="","",X6*V6) | Z6: =IF(U6="",O6,O6+U6) -> 150.77976 | AA6: =IF(X6="",R6,X6+R6) -> #DIV/0! | AB6: =IF(Y6="",S6,S6+Y6) -> #DIV/0!
A7: 3 | B7: Untergeschoss | C7: -2 | D7: Alle | F7: 03 | G7: 14.7 | H7: Vorraum | I7: Beschichtung | J7: F1-2 | K7: V | L7: =IF(K7="NV","",G7) -> 14.7 | M7: 3 | N7: =IF(K7="NV","",IF(VLOOKUP(M7,'R_Häufigkeit_Faktoren UHR'!$B$4:$I$24,7,FALSE)=0,"",VLOOKUP(M7,'R_Häufigkeit_Faktoren UHR'!$B$4:$I$24,7,FALSE))) -> 13.035714 | O7: =IF(N7="","",N7*L7) -> 191.625 | Q7: =IF(N7="","",VLOOKUP(J7,Raumgruppen_Leistungswerte!$B$5:$F$35,5,FALSE)) -> 0 | R7: =IF(N7="","",L7/Q7*N7) -> #DIV/0! | S7: =IF(K7="NV","",R7*P7) -> #DIV/0! | T7: =IF(K7="NV","",IF(VLOOKUP(M7,'R_Häufigkeit_Faktoren UHR'!$B$4:$I$24,8,FALSE)=0,"",VLOOKUP(M7,'R_Häufigkeit_Faktoren UHR'!$B$4:$I$24,8,FALSE))) | U7: =IF(T7="","",T7*L7) | W7: =IF(T7="","",VLOOKUP(J7,Raumgruppen_Leistungswerte!$B$5:$F$35,5,FALSE)) | X7: =IF(T7="","",L7/W7*T7) | Y7: =IF(T7="","",X7*V7) | Z7: =IF(U7="",O7,O7+U7) -> 191.625 | AA7: =IF(X7="",R7,X7+R7) -> #DIV/0! | AB7: =IF(Y7="",S7,S7+Y7) -> #DIV/0!
A8: 4 | B8: Untergeschoss | C8: -2 | D8: Alle | F8: 04 | G8: 53.7 | H8: Umkleide | I8: Fliesen | J8: G | K8: NV | L8: =IF(K8="NV","",G8) | N8: =IF(K8="NV","",IF(VLOOKUP(M8,'R_Häufigkeit_Faktoren UHR'!$B$4:$I$24,7,FALSE)=0,"",VLOOKUP(M8,'R_Häufigkeit_Faktoren UHR'!$B$4:$I$24,7,FALSE))) | O8: =IF(N8="","",N8*L8) | Q8: =IF(N8="","",VLOOKUP(J8,Raumgruppen_Leistungswerte!$B$5:$F$35,5,FALSE)) | R8: =IF(N8="","",L8/Q8*N8) | S8: =IF(K8="NV","",R8*P8) | T8: =IF(K8="NV","",IF(VLOOKUP(M8,'R_Häufigkeit_Faktoren UHR'!$B$4:$I$24,8,FALSE)=0,"",VLOOKUP(M8,'R_Häufigkeit_Faktoren UHR'!$B$4:$I$24,8,FALSE))) | U8: =IF(T8="","",T8*L8) | W8: =IF(T8="","",VLOOKUP(J8,Raumgruppen_Leistungswerte!$B$5:$F$35,5,FALSE)) | X8: =IF(T8="","",L8/W8*T8) | Y8: =IF(T8="","",X8*V8) | Z8: =IF(U8="",O8,O8+U8) | AA8: =IF(X8="",R8,X8+R8) | AB8: =IF(Y8="",S8,S8+Y8)
A9: 5 | B9: Untergeschoss | C9: -2 | D9: Alle | F9: 05 | G9: 264.2 | H9: Kälte + Heizung | I9: Beschichtung | J9: J | K9: NV | L9: =IF(K9="NV","",G9) | N9: =IF(K9="NV","",IF(VLOOKUP(M9,'R_Häufigkeit_Faktoren UHR'!$B$4:$I$24,7,FALSE)=0,"",VLOOKUP(M9,'R_Häufigkeit_Faktoren UHR'!$B$4:$I$24,7,FALSE))) | O9: =IF(N9="","",N9*L9) | Q9: =IF(N9="","",VLOOKUP(J9,Raumgruppen_Leistungswerte!$B$5:$F$35,5,FALSE)) | R9: =IF(N9="","",L9/Q9*N9) | S9: =IF(K9="NV","",R9*P9) | T9: =IF(K9="NV","",IF(VLOOKUP(M9,'R_Häufigkeit_Faktoren UHR'!$B$4:$I$24,8,FALSE)=0,"",VLOOKUP(M9,'R_Häufigkeit_Faktoren UHR'!$B$4:$I$24,8,FALSE))) | U9: =IF(T9="","",T9*L9) | W9: =IF(T9="","",VLOOKUP(J9,Raumgruppen_Leistungswerte!$B$5:$F$35,5,FALSE)) | X9: =IF(T9="","",L9/W9*T9) | Y9: =IF(T9="","",X9*V9) | Z9: =IF(U9="",O9,O9+U9) | AA9: =IF(X9="",R9,X9+R9) | AB9: =IF(Y9="",S9,S9+Y9)
A10: 6 | B10: Untergeschoss | C10: -2 | D10: Technik | F10: 06 | G10: 31.4 | H10: Technik | I10: Beschichtung | J10: J | K10: NV | L10: =IF(K10="NV","",G10) | N10: =IF(K10="NV","",IF(VLOOKUP(M10,'R_Häufigkeit_Faktoren UHR'!$B$4:$I$24,7,FALSE)=0,"",VLOOKUP(M10,'R_Häufigkeit_Faktoren UHR'!$B$4:$I$24,7,FALSE))) | O10: =IF(N10="","",N10*L10) | Q10: =IF(N10="","",VLOOKUP(J10,Raumgruppen_Leistungswerte!$B$5:$F$35,5,FALSE)) | R10: =IF(N10="","",L10/Q10*N10) | S10: =IF(K10="NV","",R10*P10) | T10: =IF(K10="NV","",IF(VLOOKUP(M10,'R_Häufigkeit_Faktoren UHR'!$B$4:$I$24,8,FALSE)=0,"",VLOOKUP(M10,'R_Häufigkeit_Faktoren UHR'!$B$4:$I$24,8,FALSE))) | U10: =IF(T10="","",T10*L10) | W10: =IF(T10="","",VLOOKUP(J10,Raumgruppen_Leistungswerte!$B$5:$F$35,5,FALSE)) | X10: =IF(T10="","",L10/W10*T10) | Y10: =IF(T10="","",X10*V10) | Z10: =IF(U10="",O10,O10+U10) | AA10: =IF(X10="",R10,X10+R10) | AB10: =IF(Y10="",S10,S10+Y10)
A11: 7 | B11: Untergeschoss | C11: -2 | D11: Alle | F11: 07 | G11: 41.6 | H11: Umkleide | I11: Fliesen | J11: G | K11: NV | L11: =IF(K11="NV","",G11) | N11: =IF(K11="NV","",IF(VLOOKUP(M11,'R_Häufigkeit_Faktoren UHR'!$B$4:$I$24,7,FALSE)=0,"",VLOOKUP(M11,'R_Häufigkeit_Faktoren UHR'!$B$4:$I$24,7,FALSE))) | O11: =IF(N11="","",N11*L11) | Q11: =IF(N11="","",VLOOKUP(J11,Raumgruppen_Leistungswerte!$B$5:$F$35,5,FALSE)) | R11: =IF(N11="","",L11/Q11*N11) | S11: =IF(K11="NV","",R11*P11) | T11: =IF(K11="NV","",IF(VLOOKUP(M11,'R_Häufigkeit_Faktoren UHR'!$B$4:$I$24,8,FALSE)=0,"",VLOOKUP(M11,'R_Häufigkeit_Faktoren UHR'!$B$4:$I$24,8,FALSE))) | U11: =IF(T11="","",T11*L11) | W11: =IF(T11="","",VLOOKUP(J11,Raumgruppen_Leistungswerte!$B$5:$F$35,5,FALSE)) | X11: =IF(T11="","",L11/W11*T11) | Y11: =IF(T11="","",X11*V11) | Z11: =IF(U11="",O11,O11+U11) | AA11: =IF(X11="",R11,X11+R11) | AB11: =IF(Y11="",S11,S11+Y11)
A12: 8 | B12: Untergeschoss | C12: -2 | D12: Technik | F12: 08 | G12: 14.2 | H12: Technik ELT | I12: Beschichtung | J12: J | K12: NV | L12: =IF(K12="NV","",G12) | N12: =IF(K12="NV","",IF(VLOOKUP(M12,'R_Häufigkeit_Faktoren UHR'!$B$4:$I$24,7,FALSE)=0,"",VLOOKUP(M12,'R_Häufigkeit_Faktoren UHR'!$B$4:$I$24,7,FALSE))) | O12: =IF(N12="","",N12*L12) | Q12: =IF(N12="","",VLOOKUP(J12,Raumgruppen_Leistungswerte!$B$5:$F$35,5,FALSE)) | R12: =IF(N12="","",L12/Q12*N12) | S12: =IF(K12="NV","",R12*P12) | T12: =IF(K12="NV","",IF(VLOOKUP(M12,'R_Häufigkeit_Faktoren UHR'!$B$4:$I$24,8,FALSE)=0,"",VLOOKUP(M12,'R_Häufigkeit_Faktoren UHR'!$B$4:$I$24,8,FALSE))) | U12: =IF(T12="","",T12*L12) | W12: =IF(T12="","",VLOOKUP(J12,Raumgruppen_Leistungswerte!$B$5:$F$35,5,FALSE)) | X12: =IF(T12="","",L12/W12*T12) | Y12: =IF(T12="","",X12*V12) | Z12: =IF(U12="",O12,O12+U12) | AA12: =IF(X12="",R12,X12+R12) | AB12: =IF(Y12="",S12,S12+Y12)
A13: 9 | B13: Untergeschoss | C13: -2 | D13: Technik | F13: 09 | G13: 213.9 | H13: Technik Sprinklerzentrale | I13: Beschichtung | J13: J | K13: NV | L13: =IF(K13="NV","",G13) | N13: =IF(K13="NV","",IF(VLOOKUP(M13,'R_Häufigkeit_Faktoren UHR'!$B$4:$I$24,7,FALSE)=0,"",VLOOKUP(M13,'R_Häufigkeit_Faktoren UHR'!$B$4:$I$24,7,FALSE))) | O13: =IF(N13="","",N13*L13) | Q13: =IF(N13="","",VLOOKUP(J13,Raumgruppen_Leistungswerte!$B$5:$F$35,5,FALSE)) | R13: =IF(N13="","",L13/Q13*N13) | S13: =IF(K13="NV","",R13*P13) | T13: =IF(K13="NV","",IF(VLOOKUP(M13,'R_Häufigkeit_Faktoren UHR'!$B$4:$I$24,8,FALSE)=0,"",VLOOKUP(M13,'R_Häufigkeit_Faktoren UHR'!$B$4:$I$24,8,FALSE))) | U13: =IF(T13="","",T13*L13) | W13: =IF(T13="","",VLOOKUP(J13,Raumgruppen_Leistungswerte!$B$5:$F$35,5,FALSE)) | X13: =IF(T13="","",L13/W13*T13) | Y13: =IF(T13="","",X13*V13) | Z13: =IF(U13="",O13,O13+U13) | AA13: =IF(X13="",R13,X13+R13) | AB13: =IF(Y13="",S13,S13+Y13)
A14: 10 | B14: Untergeschoss | C14: -2 | D14: Technik | F14: 10 | G14: 58.1 | H14: Sprinklertank | I14: Beschichtung | J14: J | K14: NV | L14: =IF(K14="NV","",G14) | N14: =IF(K14="NV","",IF(VLOOKUP(M14,'R_Häufigkeit_Faktoren UHR'!$B$4:$I$24,7,FALSE)=0,"",VLOOKUP(M14,'R_Häufigkeit_Faktoren UHR'!$B$4:$I$24,7,FALSE))) | O14: =IF(N14="","",N14*L14) | Q14: =IF(N14="","",VLOOKUP(J14,Raumgruppen_Leistungswerte!$B$5:$F$35,5,FALSE)) | R14: =IF(N14="","",L14/Q14*N14) | S14: =IF(K14="NV","",R14*P14) | T14: =IF(K14="NV","",IF(VLOOKUP(M14,'R_Häufigkeit_Faktoren UHR'!$B$4:$I$24,8,FALSE)=0,"",VLOOKUP(M14,'R_Häufigkeit_Faktoren UHR'!$B$4:$I$24,8,FALSE))) | U14: =IF(T14="","",T14*L14) | W14: =IF(T14="","",VLOOKUP(J14,Raumgruppen_Leistungswerte!$B$5:$F$35,5,FALSE)) | X14: =IF(T14="","",L14/W14*T14) | Y14: =IF(T14="","",X14*V14) | Z14: =IF(U14="",O14,O14+U14) | AA14: =IF(X14="",R14,X14+R14) | AB14: =IF(Y14="",S14,S14+Y14)
A15: 11 | B15: Untergeschoss | C15: -2 | D15: Alle | F15: 11 | G15: 6.4 | H15: Druckseite | I15: Beschichtung | J15: J | K15: NV | L15: =IF(K15="NV","",G15) | N15: =IF(K15="NV","",IF(VLOOKUP(M15,'R_Häufigkeit_Faktoren UHR'!$B$4:$I$24,7,FALSE)=0,"",VLOOKUP(M15,'R_Häufigkeit_Faktoren UHR'!$B$4:$I$24,7,FALSE))) | O15: =IF(N15="","",N15*L15) | Q15: =IF(N15="","",VLOOKUP(J15,Raumgruppen_Leistungswerte!$B$5:$F$35,5,FALSE)) | R15: =IF(N15="","",L15/Q15*N15) | S15: =IF(K15="NV","",R15*P15) | T15: =IF(K15="NV","",IF(VLOOKUP(M15,'R_Häufigkeit_Faktoren UHR'!$B$4:$I$24,8,FALSE)=0,"",VLOOKUP(M15,'R_Häufigkeit_Faktoren UHR'!$B$4:$I$24,8,FALSE))) | U15: =IF(T15="","",T15*L15) | W15: =IF(T15="","",VLOOKUP(J15,Raumgruppen_Leistungswerte!$B$5:$F$35,5,FALSE)) | X15: =IF(T15="","",L15/W15*T15) | Y15: =IF(T15="","",X15*V15) | Z15: =IF(U15="",O15,O15+U15) | AA15: =IF(X15="",R15,X15+R15) | AB15: =IF(Y15="",S15,S15+Y15)
A16: 12 | B16: Untergeschoss | C16: -2 | D16: Technik | F16: 12 | G16: 15.4 | H16: Saugseite | I16: Beschichtung | J16: J | K16: NV | L16: =IF(K16="NV","",G16) | N16: =IF(K16="NV","",IF(VLOOKUP(M16,'R_Häufigkeit_Faktoren UHR'!$B$4:$I$24,7,FALSE)=0,"",VLOOKUP(M16,'R_Häufigkeit_Faktoren UHR'!$B$4:$I$24,7,FALSE))) | O16: =IF(N16="","",N16*L16) | Q16: =IF(N16="","",VLOOKUP(J16,Raumgruppen_Leistungswerte!$B$5:$F$35,5,FALSE)) | R16: =IF(N16="","",L16/Q16*N16) | S16: =IF(K16="NV","",R16*P16) | T16: =IF(K16="NV","",IF(VLOOKUP(M16,'R_Häufigkeit_Faktoren UHR'!$B$4:$I$24,8,FALSE)=0,"",VLOOKUP(M16,'R_Häufigkeit_Faktoren UHR'!$B$4:$I$24,8,FALSE))) | U16: =IF(T16="","",T16*L16) | W16: =IF(T16="","",VLOOKUP(J16,Raumgruppen_Leistungswerte!$B$5:$F$35,5,FALSE)) | X16: =IF(T16="","",L16/W16*T16) | Y16: =IF(T16="","",X16*V16) | Z16: =IF(U16="",O16,O16+U16) | AA16: =IF(X16="",R16,X16+R16) | AB16: =IF(Y16="",S16,S16+Y16)
A17: 13 | B17: Untergeschoss | C17: -2 | D17: Alle | F17: 13 | G17: 42.6 | H17: Geräteraum | I17: Beschichtung | J17: J | K17: NV | L17: =IF(K17="NV","",G17) | N17: =IF(K17="NV","",IF(VLOOKUP(M17,'R_Häufigkeit_Faktoren UHR'!$B$4:$I$24,7,FALSE)=0,"",VLOOKUP(M17,'R_Häufigkeit_Faktoren UHR'!$B$4:$I$24,7,FALSE))) | O17: =IF(N17="","",N17*L17) | Q17: =IF(N17="","",VLOOKUP(J17,Raumgruppen_Leistungswerte!$B$5:$F$35,5,FALSE)) | R17: =IF(N17="","",L17/Q17*N17) | S17: =IF(K17="NV","",R17*P17) | T17: =IF(K17="NV","",IF(VLOOKUP(M17,'R_Häufigkeit_Faktoren UHR'!$B$4:$I$24,8,FALSE)=0,"",VLOOKUP(M17,'R_Häufigkeit_Faktoren UHR'!$B$4:$I$24,8,FALSE))) | U17: =IF(T17="","",T17*L17) | W17: =IF(T17="","",VLOOKUP(J17,Raumgruppen_Leistungswerte!$B$5:$F$35,5,FALSE)) | X17: =IF(T17="","",L17/W17*T17) | Y17: =IF(T17="","",X17*V17) | Z17: =IF(U17="",O17,O17+U17) | AA17: =IF(X17="",R17,X17+R17) | AB17: =IF(Y17="",S17,S17+Y17)
A18: 14 | B18: Untergeschoss | C18: -2 | D18: Technik | F18: 14 | G18: 22.1 | H18: ELT Zähler | I18: Beschichtung | J18: J | K18: NV | L18: =IF(K18="NV","",G18) | N18: =IF(K18="NV","",IF(VLOOKUP(M18,'R_Häufigkeit_Faktoren UHR'!$B$4:$I$24,7,FALSE)=0,"",VLOOKUP(M18,'R_Häufigkeit_Faktoren UHR'!$B$4:$I$24,7,FALSE))) | O18: =IF(N18="","",N18*L18) | Q18: =IF(N18="","",VLOOKUP(J18,Raumgruppen_Leistungswerte!$B$5:$F$35,5,FALSE)) | R18: =IF(N18="","",L18/Q18*N18) | S18: =IF(K18="NV","",R18*P18) | T18: =IF(K18="NV","",IF(VLOOKUP(M18,'R_Häufigkeit_Faktoren UHR'!$B$4:$I$24,8,FALSE)=0,"",VLOOKUP(M18,'R_Häufigkeit_Faktoren UHR'!$B$4:$I$24,8,FALSE))) | U18: =IF(T18="","",T18*L18) | W18: =IF(T18="","",VLOOKUP(J18,Raumgruppen_Leistungswerte!$B$5:$F$35,5,FALSE)) | X18: =IF(T18="","",L18/W18*T18) | Y18: =IF(T18="","",X18*V18) | Z18: =IF(U18="",O18,O18+U18) | AA18: =IF(X18="",R18,X18+R18) | AB18: =IF(Y18="",S18,S18+Y18)
A19: 15 | B19: Untergeschoss | C19: -2 | D19: Technik | F19: 15 | G19: 20.3 | H19: EDC Hauptzentrale | I19: Beschichtung | J19: J | K19: NV | L19: =IF(K19="NV","",G19) | N19: =IF(K19="NV","",IF(VLOOKUP(M19,'R_Häufigkeit_Faktoren UHR'!$B$4:$I$24,7,FALSE)=0,"",VLOOKUP(M19,'R_Häufigkeit_Faktoren UHR'!$B$4:$I$24,7,FALSE))) | O19: =IF(N19="","",N19*L19) | Q19: =IF(N19="","",VLOOKUP(J19,Raumgruppen_Leistungswerte!$B$5:$F$35,5,FALSE)) | R19: =IF(N19="","",L19/Q19*N19) | S19: =IF(K19="NV","",R19*P19) | T19: =IF(K19="NV","",IF(VLOOKUP(M19,'R_Häufigkeit_Faktoren UHR'!$B$4:$I$24,8,FALSE)=0,"",VLOOKUP(M19,'R_Häufigkeit_Faktoren UHR'!$B$4:$I$24,8,FALSE))) | U19: =IF(T19="","",T19*L19) | W19: =IF(T19="","",VLOOKUP(J19,Raumgruppen_Leistungswerte!$B$5:$F$35,5,FALSE)) | X19: =IF(T19="","",L19/W19*T19) | Y19: =IF(T19="","",X19*V19) | Z19: =IF(U19="",O19,O19+U19) | AA19: =IF(X19="",R19,X19+R19) | AB19: =IF(Y19="",S19,S19+Y19)
A20: 16 | B20: Untergeschoss | C20: -2 | D20: Technik | F20: 16 | G20: 7 | H20: USV | I20: Beschichtung | J20: J | K20: NV | L20: =IF(K20="NV","",G20) | N20: =IF(K20="NV","",IF(VLOOKUP(M20,'R_Häufigkeit_Faktoren UHR'!$B$4:$I$24,7,FALSE)=0,"",VLOOKUP(M20,'R_Häufigkeit_Faktoren UHR'!$B$4:$I$24,7,FALSE))) | O20: =IF(N20="","",N20*L20) | Q20: =IF(N20="","",VLOOKUP(J20,Raumgruppen_Leistungswerte!$B$5:$F$35,5,FALSE)) | R20: =IF(N20="","",L20/Q20*N20) | S20: =IF(K20="NV","",R20*P20) | T20: =IF(K20="NV","",IF(VLOOKUP(M20,'R_Häufigkeit_Faktoren UHR'!$B$4:$I$24,8,FALSE)=0,"",VLOOKUP(M20,'R_Häufigkeit_Faktoren UHR'!$B$4:$I$24,8,FALSE))) | U20: =IF(T20="","",T20*L20) | W20: =IF(T20="","",VLOOKUP(J20,Raumgruppen_Leistungswerte!$B$5:$F$35,5,FALSE)) | X20: =IF(T20="","",L20/W20*T20) | Y20: =IF(T20="","",X20*V20) | Z20: =IF(U20="",O20,O20+U20) | AA20: =IF(X20="",R20,X20+R20) | AB20: =IF(Y20="",S20,S20+Y20)
A21: 17 | B21: Untergeschoss | C21: -2 | D21: Alle | F21: 17 | G21: 8 | H21: BMA | I21: Beschichtung | J21: J | K21: NV | L21: =IF(K21="NV","",G21) | N21: =IF(K21="NV","",IF(VLOOKUP(M21,'R_Häufigkeit_Faktoren UHR'!$B$4:$I$24,7,FALSE)=0,"",VLOOKUP(M21,'R_Häufigkeit_Faktoren UHR'!$B$4:$I$24,7,FALSE))) | O21: =IF(N21="","",N21*L21) | Q21: =IF(N21="","",VLOOKUP(J21,Raumgruppen_Leistungswerte!$B$5:$F$35,5,FALSE)) | R21: =IF(N21="","",L21/Q21*N21) | S21: =IF(K21="NV","",R21*P21) | T21: =IF(K21="NV","",IF(VLOOKUP(M21,'R_Häufigkeit_Faktoren UHR'!$B$4:$I$24,8,FALSE)=0,"",VLOOKUP(M21,'R_Häufigkeit_Faktoren UHR'!$B$4:$I$24,8,FALSE))) | U21: =IF(T21="","",T21*L21) | W21: =IF(T21="","",VLOOKUP(J21,Raumgruppen_Leistungswerte!$B$5:$F$35,5,FALSE)) | X21: =IF(T21="","",L21/W21*T21) | Y21: =IF(T21="","",X21*V21) | Z21: =IF(U21="",O21,O21+U21) | AA21: =IF(X21="",R21,X21+R21) | AB21: =IF(Y21="",S21,S21+Y21)
... A26: 22 | B26: Untergeschoss | C26: -2 | D26: Technik | F26: 22 | G26: 43.8 | H26: Außenluft | I26: Beschichtung | J26: J | K26: NV | L26: =IF(K26="NV","",G26) | N26: =IF(K26="NV","",IF(VLOOKUP(M26,'R_Häufigkeit_Faktoren UHR'!$B$4:$I$24,7,FALSE)=0,"",VLOOKUP(M26,'R_Häufigkeit_Faktoren UHR'!$B$4:$I$24,7,FALSE))) | O26: =IF(N26="","",N26*L26) | Q26: =IF(N26="","",VLOOKUP(J26,Raumgruppen_Leistungswerte!$B$5:$F$35,5,FALSE)) | R26: =IF(N26="","",L26/Q26*N26) | S26: =IF(K26="NV","",R26*P26) | T26: =IF(K26="NV","",IF(VLOOKUP(M26,'R_Häufigkeit_Faktoren UHR'!$B$4:$I$24,8,FALSE)=0,"",VLOOKUP(M26,'R_Häufigkeit_Faktoren UHR'!$B$4:$I$24,8,FALSE))) | U26: =IF(T26="","",T26*L26) | W26: =IF(T26="","",VLOOKUP(J26,Raumgruppen_Leistungswerte!$B$5:$F$35,5,FALSE)) | X26: =IF(T26="","",L26/W26*T26) | Y26: =IF(T26="","",X26*V26) | Z26: =IF(U26="",O26,O26+U26) | AA26: =IF(X26="",R26,X26+R26) | AB26: =IF(Y26="",S26,S26+Y26)
A27: 23 | B27: Untergeschoss | C27: -2 | D27: Alle | F27: 23 | G27: 17.2 | H27: Flur | I27: Beschichtung | J27: F1-2 | K27: V | L27: =IF(K27="NV","",G27) -> 17.2 | M27: 5 | N27: =IF(K27="NV","",IF(VLOOKUP(M27,'R_Häufigkeit_Faktoren UHR'!$B$4:$I$24,7,FALSE)=0,"",VLOOKUP(M27,'R_Häufigkeit_Faktoren UHR'!$B$4:$I$24,7,FALSE))) -> 20.917857 | O27: =IF(N27="","",N27*L27) -> 359.78714 | Q27: =IF(N27="","",VLOOKUP(J27,Raumgruppen_Leistungswerte!$B$5:$F$35,5,FALSE)) -> 0 | R27: =IF(N27="","",L27/Q27*N27) -> #DIV/0! | S27: =IF(K27="NV","",R27*P27) -> #DIV/0! | T27: =IF(K27="NV","",IF(VLOOKUP(M27,'R_Häufigkeit_Faktoren UHR'!$B$4:$I$24,8,FALSE)=0,"",VLOOKUP(M27,'R_Häufigkeit_Faktoren UHR'!$B$4:$I$24,8,FALSE))) | U27: =IF(T27="","",T27*L27) | W27: =IF(T27="","",VLOOKUP(J27,Raumgruppen_Leistungswerte!$B$5:$F$35,5,FALSE)) | X27: =IF(T27="","",L27/W27*T27) | Y27: =IF(T27="","",X27*V27) | Z27: =IF(U27="",O27,O27+U27) -> 359.78714 | AA27: =IF(X27="",R27,X27+R27) -> #DIV/0! | AB27: =IF(Y27="",S27,S27+Y27) -> #DIV/0!
A28: 24 | B28: Untergeschoss | C28: -2 | D28: Alle | F28: 24 | G28: 24.8 | H28: ZBV | I28: Beschichtung | J28: J | K28: NV | L28: =IF(K28="NV","",G28) | N28: =IF(K28="NV","",IF(VLOOKUP(M28,'R_Häufigkeit_Faktoren UHR'!$B$4:$I$24,7,FALSE)=0,"",VLOOKUP(M28,'R_Häufigkeit_Faktoren UHR'!$B$4:$I$24,7,FALSE))) | O28: =IF(N28="","",N28*L28) | Q28: =IF(N28="","",VLOOKUP(J28,Raumgruppen_Leistungswerte!$B$5:$F$35,5,FALSE)) | R28: =IF(N28="","",L28/Q28*N28) | S28: =IF(K28="NV","",R28*P28) | T28: =IF(K28="NV","",IF(VLOOKUP(M28,'R_Häufigkeit_Faktoren UHR'!$B$4:$I$24,8,FALSE)=0,"",VLOOKUP(M28,'R_Häufigkeit_Faktoren UHR'!$B$4:$I$24,8,FALSE))) | U28: =IF(T28="","",T28*L28) | W28: =IF(T28="","",VLOOKUP(J28,Raumgruppen_Leistungswerte!$B$5:$F$35,5,FALSE)) | X28: =IF(T28="","",L28/W28*T28) | Y28: =IF(T28="","",X28*V28) | Z28: =IF(U28="",O28,O28+U28) | AA28: =IF(X28="",R28,X28+R28) | AB28: =IF(Y28="",S28,S28+Y28)
A29: 25 | B29: Untergeschoss | C29: -2 | D29: Alle | F29: 25 | G29: 22.6 | H29: ZBV | I29: Beschichtung | J29: J | K29: NV | L29: =IF(K29="NV","",G29) | N29: =IF(K29="NV","",IF(VLOOKUP(M29,'R_Häufigkeit_Faktoren UHR'!$B$4:$I$24,7,FALSE)=0,"",VLOOKUP(M29,'R_Häufigkeit_Faktoren UHR'!$B$4:$I$24,7,FALSE))) | O29: =IF(N29="","",N29*L29) | Q29: =IF(N29="","",VLOOKUP(J29,Raumgruppen_Leistungswerte!$B$5:$F$35,5,FALSE)) | R29: =IF(N29="","",L29/Q29*N29) | S29: =IF(K29="NV","",R29*P29) | T29: =IF(K29="NV","",IF(VLOOKUP(M29,'R_Häufigkeit_Faktoren UHR'!$B$4:$I$24,8,FALSE)=0,"",VLOOKUP(M29,'R_Häufigkeit_Faktoren UHR'!$B$4:$I$24,8,FALSE))) | U29: =IF(T29="","",T29*L29) | W29: =IF(T29="","",VLOOKUP(J29,Raumgruppen_Leistungswerte!$B$5:$F$35,5,FALSE)) | X29: =IF(T29="","",L29/W29*T29) | Y29: =IF(T29="","",X29*V29) | Z29: =IF(U29="",O29,O29+U29) | AA29: =IF(X29="",R29,X29+R29) | AB29: =IF(Y29="",S29,S29+Y29)
A30: 26 | B30: Untergeschoss | C30: -2 | D30: Alle | F30: 26 | G30: 12.7 | H30: Fahrräder | I30: Beschichtung | J30: K | K30: V | L30: =IF(K30="NV","",G30) -> 12.7 | M30: Q1 | N30: =IF(K30="NV","",IF(VLOOKUP(M30,'R_Häufigkeit_Faktoren UHR'!$B$4:$I$24,7,FALSE)=0,"",VLOOKUP(M30,'R_Häufigkeit_Faktoren UHR'!$B$4:$I$24,7,FALSE))) -> 4 | O30: =IF(N30="","",N30*L30) -> 50.8 | Q30: =IF(N30="","",VLOOKUP(J30,Raumgruppen_Leistungswerte!$B$5:$F$35,5,FALSE)) -> 0 | R30: =IF(N30="","",L30/Q30*N30) -> #DIV/0! | S30: =IF(K30="NV","",R30*P30) -> #DIV/0! | T30: =IF(K30="NV","",IF(VLOOKUP(M30,'R_Häufigkeit_Faktoren UHR'!$B$4:$I$24,8,FALSE)=0,"",VLOOKUP(M30,'R_Häufigkeit_Faktoren UHR'!$B$4:$I$24,8,FALSE))) | U30: =IF(T30="","",T30*L30) | W30: =IF(T30="","",VLOOKUP(J30,Raumgruppen_Leistungswerte!$B$5:$F$35,5,FALSE)) | X30: =IF(T30="","",L30/W30*T30) | Y30: =IF(T30="","",X30*V30) | Z30: =IF(U30="",O30,O30+U30) -> 50.8 | AA30: =IF(X30="",R30,X30+R30) -> #DIV/0! | AB30: =IF(Y30="",S30,S30+Y30) -> #DIV/0!
A31: 27 | B31: Untergeschoss | C31: -2 | D31: Alle | F31: 27 | G31: 32 | H31: Flur | I31: Beschichtung | J31: F1-2 | K31: V | L31: =IF(K31="NV","",G31) -> 32 | M31: 5 | N31: =IF(K31="NV","",IF(VLOOKUP(M31,'R_Häufigkeit_Faktoren UHR'!$B$4:$I$24,7,FALSE)=0,"",VLOOKUP(M31,'R_Häufigkeit_Faktoren UHR'!$B$4:$I$24,7,FALSE))) -> 20.917857 | O31: =IF(N31="","",N31*L31) -> 669.37143 | Q31: =IF(N31="","",VLOOKUP(J31,Raumgruppen_Leistungswerte!$B$5:$F$35,5,FALSE)) -> 0 | R31: =IF(N31="","",L31/Q31*N31) -> #DIV/0! | S31: =IF(K31="NV","",R31*P31) -> #DIV/0! | T31: =IF(K31="NV","",IF(VLOOKUP(M31,'R_Häufigkeit_Faktoren UHR'!$B$4:$I$24,8,FALSE)=0,"",VLOOKUP(M31,'R_Häufigkeit_Faktoren UHR'!$B$4:$I$24,8,FALSE))) | U31: =IF(T31="","",T31*L31) | W31: =IF(T31="","",VLOOKUP(J31,Raumgruppen_Leistungswerte!$B$5:$F$35,5,FALSE)) | X31: =IF(T31="","",L31/W31*T31) | Y31: =IF(T31="","",X31*V31) | Z31: =IF(U31="",O31,O31+U31) -> 669.37143 | AA31: =IF(X31="",R31,X31+R31) -> #DIV/0! | AB31: =IF(Y31="",S31,S31+Y31) -> #DIV/0!
A32: 28 | B32: Untergeschoss | C32: -2 | D32: Alle | F32: 28 | G32: 10.2 | H32: Reinigungsmittel | I32: ? | J32: J | K32: NV | L32: =IF(K32="NV","",G32) | N32: =IF(K32="NV","",IF(VLOOKUP(M32,'R_Häufigkeit_Faktoren UHR'!$B$4:$I$24,7,FALSE)=0,"",VLOOKUP(M32,'R_Häufigkeit_Faktoren UHR'!$B$4:$I$24,7,FALSE))) | O32: =IF(N32="","",N32*L32) | Q32: =IF(N32="","",VLOOKUP(J32,Raumgruppen_Leistungswerte!$B$5:$F$35,5,FALSE)) | R32: =IF(N32="","",L32/Q32*N32) | S32: =IF(K32="NV","",R32*P32) | T32: =IF(K32="NV","",IF(VLOOKUP(M32,'R_Häufigkeit_Faktoren UHR'!$B$4:$I$24,8,FALSE)=0,"",VLOOKUP(M32,'R_Häufigkeit_Faktoren UHR'!$B$4:$I$24,8,FALSE))) | U32: =IF(T32="","",T32*L32) | W32: =IF(T32="","",VLOOKUP(J32,Raumgruppen_Leistungswerte!$B$5:$F$35,5,FALSE)) | X32: =IF(T32="","",L32/W32*T32) | Y32: =IF(T32="","",X32*V32) | Z32: =IF(U32="",O32,O32+U32) | AA32: =IF(X32="",R32,X32+R32) | AB32: =IF(Y32="",S32,S32+Y32)
A33: 29 | B33: Untergeschoss | C33: -2 | D33: Alle | F33: 29 | G33: 14.1 | H33: Umkleide Lager | I33: Beschichtung | J33: G | K33: NV | L33: =IF(K33="NV","",G33) | N33: =IF(K33="NV","",IF(VLOOKUP(M33,'R_Häufigkeit_Faktoren UHR'!$B$4:$I$24,7,FALSE)=0,"",VLOOKUP(M33,'R_Häufigkeit_Faktoren UHR'!$B$4:$I$24,7,FALSE))) | O33: =IF(N33="","",N33*L33) | Q33: =IF(N33="","",VLOOKUP(J33,Raumgruppen_Leistungswerte!$B$5:$F$35,5,FALSE)) | R33: =IF(N33="","",L33/Q33*N33) | S33: =IF(K33="NV","",R33*P33) | T33: =IF(K33="NV","",IF(VLOOKUP(M33,'R_Häufigkeit_Faktoren UHR'!$B$4:$I$24,8,FALSE)=0,"",VLOOKUP(M33,'R_Häufigkeit_Faktoren UHR'!$B$4:$I$24,8,FALSE))) | U33: =IF(T33="","",T33*L33) | W33: =IF(T33="","",VLOOKUP(J33,Raumgruppen_Leistungswerte!$B$5:$F$35,5,FALSE)) | X33: =IF(T33="","",L33/W33*T33) | Y33: =IF(T33="","",X33*V33) | Z33: =IF(U33="",O33,O33+U33) | AA33: =IF(X33="",R33,X33+R33) | AB33: =IF(Y33="",S33,S33+Y33)
A34: 30 | B34: Untergeschoss | C34: -2 | D34: Technik | F34: 30 | G34: 16.8 | H34: Technik Lüftung | I34: Beschichtung | J34: J | K34: NV | L34: =IF(K34="NV","",G34) | N34: =IF(K34="NV","",IF(VLOOKUP(M34,'R_Häufigkeit_Faktoren UHR'!$B$4:$I$24,7,FALSE)=0,"",VLOOKUP(M34,'R_Häufigkeit_Faktoren UHR'!$B$4:$I$24,7,FALSE))) | O34: =IF(N34="","",N34*L34) | Q34: =IF(N34="","",VLOOKUP(J34,Raumgruppen_Leistungswerte!$B$5:$F$35,5,FALSE)) | R34: =IF(N34="","",L34/Q34*N34) | S34: =IF(K34="NV","",R34*P34) | T34: =IF(K34="NV","",IF(VLOOKUP(M34,'R_Häufigkeit_Faktoren UHR'!$B$4:$I$24,8,FALSE)=0,"",VLOOKUP(M34,'R_Häufigkeit_Faktoren UHR'!$B$4:$I$24,8,FALSE))) | U34: =IF(T34="","",T34*L34) | W34: =IF(T34="","",VLOOKUP(J34,Raumgruppen_Leistungswerte!$B$5:$F$35,5,FALSE)) | X34: =IF(T34="","",L34/W34*T34) | Y34: =IF(T34="","",X34*V34) | Z34: =IF(U34="",O34,O34+U34) | AA34: =IF(X34="",R34,X34+R34) | AB34: =IF(Y34="",S34,S34+Y34)
A35: 31 | B35: Untergeschoss | C35: -2 | D35: Alle | F35: TH1-01 | G35: 20.3 | H35: Treppenhaus | I35: Betonwerkstein | J35: F2-1 | K35: V | L35: =IF(K35="NV","",G35) -> 20.3 | M35: 3 | N35: =IF(K35="NV","",IF(VLOOKUP(M35,'R_Häufigkeit_Faktoren UHR'!$B$4:$I$24,7,FALSE)=0,"",VLOOKUP(M35,'R_Häufigkeit_Faktoren UHR'!$B$4:$I$24,7,FALSE))) -> 13.035714 | O35: =IF(N35="","",N35*L35) -> 264.625 | Q35: =IF(N35="","",VLOOKUP(J35,Raumgruppen_Leistungswerte!$B$5:$F$35,5,FALSE)) -> 0 | R35: =IF(N35="","",L35/Q35*N35) -> #DIV/0! | S35: =IF(K35="NV","",R35*P35) -> #DIV/0! | T35: =IF(K35="NV","",IF(VLOOKUP(M35,'R_Häufigkeit_Faktoren UHR'!$B$4:$I$24,8,FALSE)=0,"",VLOOKUP(M35,'R_Häufigkeit_Faktoren UHR'!$B$4:$I$24,8,FALSE))) | U35: =IF(T35="","",T35*L35) | W35: =IF(T35="","",VLOOKUP(J35,Raumgruppen_Leistungswerte!$B$5:$F$35,5,FALSE)) | X35: =IF(T35="","",L35/W35*T35) | Y35: =IF(T35="","",X35*V35) | Z35: =IF(U35="",O35,O35+U35) -> 264.625 | AA35: =IF(X35="",R35,X35+R35) -> #DIV/0! | AB35: =IF(Y35="",S35,S35+Y35) -> #DIV/0!
A36: 32 | B36: Untergeschoss | C36: -2 | D36: Technik | F36: TH1-02 | G36: 15.4 | H36: Schleuse | I36: Betonwerkstein | J36: F2-1 | K36: V | L36: =IF(K36="NV","",G36) -> 15.4 | M36: 3 | N36: =IF(K36="NV","",IF(VLOOKUP(M36,'R_Häufigkeit_Faktoren UHR'!$B$4:$I$24,7,FALSE)=0,"",VLOOKUP(M36,'R_Häufigkeit_Faktoren UHR'!$B$4:$I$24,7,FALSE))) -> 13.035714 | O36: =IF(N36="","",N36*L36) -> 200.75 | Q36: =IF(N36="","",VLOOKUP(J36,Raumgruppen_Leistungswerte!$B$5:$F$35,5,FALSE)) -> 0 | R36: =IF(N36="","",L36/Q36*N36) -> #DIV/0! | S36: =IF(K36="NV","",R36*P36) -> #DIV/0! | T36: =IF(K36="NV","",IF(VLOOKUP(M36,'R_Häufigkeit_Faktoren UHR'!$B$4:$I$24,8,FALSE)=0,"",VLOOKUP(M36,'R_Häufigkeit_Faktoren UHR'!$B$4:$I$24,8,FALSE))) | U36: =IF(T36="","",T36*L36) | W36: =IF(T36="","",VLOOKUP(J36,Raumgruppen_Leistungswerte!$B$5:$F$35,5,FALSE)) | X36: =IF(T36="","",L36/W36*T36) | Y36: =IF(T36="","",X36*V36) | Z36: =IF(U36="",O36,O36+U36) -> 200.75 | AA36: =IF(X36="",R36,X36+R36) -> #DIV/0! | AB36: =IF(Y36="",S36,S36+Y36) -> #DIV/0!
A37: 33 | B37: Untergeschoss | C37: -2 | D37: Alle | F37: TH1-03 | G37: 16.7 | H37: Vorraum | I37: Betonwerkstein | J37: F2-1 | K37: V | L37: =IF(K37="NV","",G37) -> 16.7 | M37: 5 | N37: =IF(K37="NV","",IF(VLOOKUP(M37,'R_Häufigkeit_Faktoren UHR'!$B$4:$I$24,7,FALSE)=0,"",VLOOKUP(M37,'R_Häufigkeit_Faktoren UHR'!$B$4:$I$24,7,FALSE))) -> 20.917857 | O37: =IF(N37="","",N37*L37) -> 349.32821 | Q37: =IF(N37="","",VLOOKUP(J37,Raumgruppen_Leistungswerte!$B$5:$F$35,5,FALSE)) -> 0 | R37: =IF(N37="","",L37/Q37*N37) -> #DIV/0! | S37: =IF(K37="NV","",R37*P37) -> #DIV/0! | T37: =IF(K37="NV","",IF(VLOOKUP(M37,'R_Häufigkeit_Faktoren UHR'!$B$4:$I$24,8,FALSE)=0,"",VLOOKUP(M37,'R_Häufigkeit_Faktoren UHR'!$B$4:$I$24,8,FALSE))) | U37: =IF(T37="","",T37*L37) | W37: =IF(T37="","",VLOOKUP(J37,Raumgruppen_Leistungswerte!$B$5:$F$35,5,FALSE)) | X37: =IF(T37="","",L37/W37*T37) | Y37: =IF(T37="","",X37*V37) | Z37: =IF(U37="",O37,O37+U37) -> 349.32821 | AA37: =IF(X37="",R37,X37+R37) -> #DIV/0! | AB37: =IF(Y37="",S37,S37+Y37) -> #DIV/0!
A38: 34 | B38: Untergeschoss | C38: -2 | D38: Technik | F38: TH1-04 | G38: 28.7 | H38: Schleuse | I38: Betonwerkstein | J38: F2-1 | K38: V | L38: =IF(K38="NV","",G38) -> 28.7 | M38: 3 | N38: =IF(K38="NV","",IF(VLOOKUP(M38,'R_Häufigkeit_Faktoren UHR'!$B$4:$I$24,7,FALSE)=0,"",VLOOKUP(M38,'R_Häufigkeit_Faktoren UHR'!$B$4:$I$24,7,FALSE))) -> 13.035714 | O38: =IF(N38="","",N38*L38) -> 374.125 | Q38: =IF(N38="","",VLOOKUP(J38,Raumgruppen_Leistungswerte!$B$5:$F$35,5,FALSE)) -> 0 | R38: =IF(N38="","",L38/Q38*N38) -> #DIV/0! | S38: =IF(K38="NV","",R38*P38) -> #DIV/0! | T38: =IF(K38="NV","",IF(VLOOKUP(M38,'R_Häufigkeit_Faktoren UHR'!$B$4:$I$24,8,FALSE)=0,"",VLOOKUP(M38,'R_Häufigkeit_Faktoren UHR'!$B$4:$I$24,8,FALSE))) | U38: =IF(T38="","",T38*L38) | W38: =IF(T38="","",VLOOKUP(J38,Raumgruppen_Leistungswerte!$B$5:$F$35,5,FALSE)) | X38: =IF(T38="","",L38/W38*T38) | Y38: =IF(T38="","",X38*V38) | Z38: =IF(U38="",O38,O38+U38) -> 374.125 | AA38: =IF(X38="",R38,X38+R38) -> #DIV/0! | AB38: =IF(Y38="",S38,S38+Y38) -> #DIV/0!
A39: 35 | B39: Untergeschoss | C39: -2 | D39: Alle | F39: TH2-01 | G39: 23.8 | H39: Treppenhaus | I39: Betonwerkstein | J39: F2-1 | K39: V | L39: =IF(K39="NV","",G39) -> 23.8 | M39: 3 | N39: =IF(K39="NV","",IF(VLOOKUP(M39,'R_Häufigkeit_Faktoren UHR'!$B$4:$I$24,7,FALSE)=0,"",VLOOKUP(M39,'R_Häufigkeit_Faktoren UHR'!$B$4:$I$24,7,FALSE))) -> 13.035714 | O39: =IF(N39="","",N39*L39) -> 310.25 | Q39: =IF(N39="","",VLOOKUP(J39,Raumgruppen_Leistungswerte!$B$5:$F$35,5,FALSE)) -> 0 | R39: =IF(N39="","",L39/Q39*N39) -> #DIV/0! | S39: =IF(K39="NV","",R39*P39) -> #DIV/0! | T39: =IF(K39="NV","",IF(VLOOKUP(M39,'R_Häufigkeit_Faktoren UHR'!$B$4:$I$24,8,FALSE)=0,"",VLOOKUP(M39,'R_Häufigkeit_Faktoren UHR'!$B$4:$I$24,8,FALSE))) | U39: =IF(T39="","",T39*L39) | W39: =IF(T39="","",VLOOKUP(J39,Raumgruppen_Leistungswerte!$B$5:$F$35,5,FALSE)) | X39: =IF(T39="","",L39/W39*T39) | Y39: =IF(T39="","",X39*V39) | Z39: =IF(U39="",O39,O39+U39) -> 310.25 | AA39: =IF(X39="",R39,X39+R39) -> #DIV/0! | AB39: =IF(Y39="",S39,S39+Y39) -> #DIV/0!
A40: 36 | B40: Untergeschoss | C40: -2 | D40: Technik | F40: TH2-02 | G40: 18.2 | H40: Schleuse | I40: Betonwerkstein | J40: F2-1 | K40: V | L40: =IF(K40="NV","",G40) -> 18.2 | M40: 3 | N40: =IF(K40="NV","",IF(VLOOKUP(M40,'R_Häufigkeit_Faktoren UHR'!$B$4:$I$24,7,FALSE)=0,"",VLOOKUP(M40,'R_Häufigkeit_Faktoren UHR'!$B$4:$I$24,7,FALSE))) -> 13.035714 | O40: =IF(N40="","",N40*L40) -> 237.25 | Q40: =IF(N40="","",VLOOKUP(J40,Raumgruppen_Leistungswerte!$B$5:$F$35,5,FALSE)) -> 0 | R40: =IF(N40="","",L40/Q40*N40) -> #DIV/0! | S40: =IF(K40="NV","",R40*P40) -> #DIV/0! | T40: =IF(K40="NV","",IF(VLOOKUP(M40,'R_Häufigkeit_Faktoren UHR'!$B$4:$I$24,8,FALSE)=0,"",VLOOKUP(M40,'R_Häufigkeit_Faktoren UHR'!$B$4:$I$24,8,FALSE))) | U40: =IF(T40="","",T40*L40) | W40: =IF(T40="","",VLOOKUP(J40,Raumgruppen_Leistungswerte!$B$5:$F$35,5,FALSE)) | X40: =IF(T40="","",L40/W40*T40) | Y40: =IF(T40="","",X40*V40) | Z40: =IF(U40="",O40,O40+U40) -> 237.25 | AA40: =IF(X40="",R40,X40+R40) -> #DIV/0! | AB40: =IF(Y40="",S40,S40+Y40) -> #DIV/0!
A41: 37 | B41: Untergeschoss | C41: -2 | D41: Alle | F41: TH2-03 | G41: 7 | H41: Vorraum | I41: Betonwerkstein | J41: F2-1 | K41: V | L41: =IF(K41="NV","",G41) -> 7 | M41: 5 | N41: =IF(K41="NV","",IF(VLOOKUP(M41,'R_Häufigkeit_Faktoren UHR'!$B$4:$I$24,7,FALSE)=0,"",VLOOKUP(M41,'R_Häufigkeit_Faktoren UHR'!$B$4:$I$24,7,FALSE))) -> 20.917857 | O41: =IF(N41="","",N41*L41) -> 146.425 | Q41: =IF(N41="","",VLOOKUP(J41,Raumgruppen_Leistungswerte!$B$5:$F$35,5,FALSE)) -> 0 | R41: =IF(N41="","",L41/Q41*N41) -> #DIV/0! | S41: =IF(K41="NV","",R41*P41) -> #DIV/0! | T41: =IF(K41="NV","",IF(VLOOKUP(M41,'R_Häufigkeit_Faktoren UHR'!$B$4:$I$24,8,FALSE)=0,"",VLOOKUP(M41,'R_Häufigkeit_Faktoren UHR'!$B$4:$I$24,8,FALSE))) | U41: =IF(T41="","",T41*L41) | W41: =IF(T41="","",VLOOKUP(J41,Raumgruppen_Leistungswerte!$B$5:$F$35,5,FALSE)) | X41: =IF(T41="","",L41/W41*T41) | Y41: =IF(T41="","",X41*V41) | Z41: =IF(U41="",O41,O41+U41) -> 146.425 | AA41: =IF(X41="",R41,X41+R41) -> #DIV/0! | AB41: =IF(Y41="",S41,S41+Y41) -> #DIV/0!
A42: 38 | B42: Untergeschoss | C42: -2 | D42: Alle | F42: VF01 | G42: 2889.3 | H42: Verkehsfläche | I42: Beschichtung | J42: K | K42: NV | L42: =IF(K42="NV","",G42) | M42: J2 | N42: =IF(K42="NV","",IF(VLOOKUP(M42,'R_Häufigkeit_Faktoren UHR'!$B$4:$I$24,7,FALSE)=0,"",VLOOKUP(M42,'R_Häufigkeit_Faktoren UHR'!$B$4:$I$24,7,FALSE))) | O42: =IF(N42="","",N42*L42) | Q42: =IF(N42="","",VLOOKUP(J42,Raumgruppen_Leistungswerte!$B$5:$F$35,5,FALSE)) | R42: =IF(N42="","",L42/Q42*N42) | S42: =IF(K42="NV","",R42*P42) | T42: =IF(K42="NV","",IF(VLOOKUP(M42,'R_Häufigkeit_Faktoren UHR'!$B$4:$I$24,8,FALSE)=0,"",VLOOKUP(M42,'R_Häufigkeit_Faktoren UHR'!$B$4:$I$24,8,FALSE))) | U42: =IF(T42="","",T42*L42) | W42: =IF(T42="","",VLOOKUP(J42,Raumgruppen_Leistungswerte!$B$5:$F$35,5,FALSE)) | X42: =IF(T42="","",L42/W42*T42) | Y42: =IF(T42="","",X42*V42) | Z42: =IF(U42="",O42,O42+U42) | AA42: =IF(X42="",R42,X42+R42) | AB42: =IF(Y42="",S42,S42+Y42)
A43: 39 | B43: Untergeschoss | C43: -2 | D43: Alle | F43: TH4-01 | G43: 34.2 | H43: Treppenhaus | I43: Betonwerkstein | J43: F2-1 | K43: V | L43: =IF(K43="NV","",G43) -> 34.2 | M43: 3 | N43: =IF(K43="NV","",IF(VLOOKUP(M43,'R_Häufigkeit_Faktoren UHR'!$B$4:$I$24,7,FALSE)=0,"",VLOOKUP(M43,'R_Häufigkeit_Faktoren UHR'!$B$4:$I$24,7,FALSE))) -> 13.035714 | O43: =IF(N43="","",N43*L43) -> 445.82143 | Q43: =IF(N43="","",VLOOKUP(J43,Raumgruppen_Leistungswerte!$B$5:$F$35,5,FALSE)) -> 0 | R43: =IF(N43="","",L43/Q43*N43) -> #DIV/0! | S43: =IF(K43="NV","",R43*P43) -> #DIV/0! | T43: =IF(K43="NV","",IF(VLOOKUP(M43,'R_Häufigkeit_Faktoren UHR'!$B$4:$I$24,8,FALSE)=0,"",VLOOKUP(M43,'R_Häufigkeit_Faktoren UHR'!$B$4:$I$24,8,FALSE))) | U43: =IF(T43="","",T43*L43) | W43: =IF(T43="","",VLOOKUP(J43,Raumgruppen_Leistungswerte!$B$5:$F$35,5,FALSE)) | X43: =IF(T43="","",L43/W43*T43) | Y43: =IF(T43="","",X43*V43) | Z43: =IF(U43="",O43,O43+U43) -> 445.82143 | AA43: =IF(X43="",R43,X43+R43) -> #DIV/0! | AB43: =IF(Y43="",S43,S43+Y43) -> #DIV/0!
A44: 40 | B44: Untergeschoss | C44: -2 | D44: Technik | F44: TH4-02 | G44: 3.9 | H44: Schleuse | I44: Betonwerkstein | J44: F2-1 | K44: V | L44: =IF(K44="NV","",G44) -> 3.9 | M44: 3 | N44: =IF(K44="NV","",IF(VLOOKUP(M44,'R_Häufigkeit_Faktoren UHR'!$B$4:$I$24,7,FALSE)=0,"",VLOOKUP(M44,'R_Häufigkeit_Faktoren UHR'!$B$4:$I$24,7,FALSE))) -> 13.035714 | O44: =IF(N44="","",N44*L44) -> 50.839286 | Q44: =IF(N44="","",VLOOKUP(J44,Raumgruppen_Leistungswerte!$B$5:$F$35,5,FALSE)) -> 0 | R44: =IF(N44="","",L44/Q44*N44) -> #DIV/0! | S44: =IF(K44="NV","",R44*P44) -> #DIV/0! | T44: =IF(K44="NV","",IF(VLOOKUP(M44,'R_Häufigkeit_Faktoren UHR'!$B$4:$I$24,8,FALSE)=0,"",VLOOKUP(M44,'R_Häufigkeit_Faktoren UHR'!$B$4:$I$24,8,FALSE))) | U44: =IF(T44="","",T44*L44) | W44: =IF(T44="","",VLOOKUP(J44,Raumgruppen_Leistungswerte!$B$5:$F$35,5,FALSE)) | X44: =IF(T44="","",L44/W44*T44) | Y44: =IF(T44="","",X44*V44) | Z44: =IF(U44="",O44,O44+U44) -> 50.839286 | AA44: =IF(X44="",R44,X44+R44) -> #DIV/0! | AB44: =IF(Y44="",S44,S44+Y44) -> #DIV/0!
...

Sheet Berechnung SVS
B1: Vom Anbieter auszufüllen!
B3: Kalkulation der Stundenverrechnungssätze 100% sozialversicherunspflichtiges Personal | E3: Innen- und Unterhaltsreinigung lt. Raumbuch
E5: Montag - Samstag | H5: Sonntag / Feiertag
E6: % | F6: EURO | H6: % | I6: EURO
B7: Tariflohn/ Grundlohn (Spalte Sonn-/ Feiertage inkl. aller Zuschläge [u.A. hohe Feiertage]) | E7: 1 | H7: 1
B8: 1 | C8: LOHNGEBUNDENE KOSTEN
C9: 1.1 | D9: Rentenversicherung | F9: =E9*$F$7 -> 0 | I9: =H9*$I$7 -> 0
C10: 1.2 | D10: Krankenversicherung | F10: =E10*$F$7 -> 0 | I10: =H10*$I$7 -> 0
C11: 1.3 | D11: Arbeitslosenversicherung | F11: =E11*$F$7 -> 0 | I11: =H11*$I$7 -> 0
C12: 1.4 | D12: Pflegeversicherung | F12: =E12*$F$7 -> 0 | I12: =H12*$I$7 -> 0
C13: 1.5 | D13: Gesetzliche Unfallversicherung | F13: =E13*$F$7 -> 0 | I13: =H13*$I$7 -> 0
C14: 1.6 | D14: Sonstige lohngebundene Kosten | F14: =E14*$F$7 -> 0 | I14: =H14*$I$7 -> 0
B15: SUMME Position 1 | E15: =SUM(E9:E14) -> 0 | F15: =SUM(F9:F14) -> 0 | H15: =SUM(H9:H14) -> 0 | I15: =SUM(I9:I14) -> 0
B16: 2 | C16: LOHNFOLGEKOSTEN
C17: 2.1 | D17: Urlaubsentgelt | F17: =E17*$F$7 -> 0 | I17: =H17*$I$7 -> 0
C18: 2.2 | D18: Sozialversicherung auf Urlaubsentgelt | F18: =E18*$F$7 -> 0 | I18: =H18*$I$7 -> 0
C19: 2.3 | D19: zusätzliches Urlaubsgeld | F19: =E19*$F$7 -> 0 | I19: =H19*$I$7 -> 0
C20: 2.4 | D20: Sozialversicherung auf zusätzliches Urlaubsentgelt | F20: =E20*$F$7 -> 0 | I20: =H20*$I$7 -> 0
C21: 2.5 | D21: Gesetzliche Feiertage | F21: =E21*$F$7 -> 0 | I21: =H21*$I$7 -> 0
C22: 2.6 | D22: Sozialversicherung auf Feiertage | F22: =E22*$F$7 -> 0 | I22: =H22*$I$7 -> 0
C23: 2.7 | D23: Gesetzliche Lohnfortzahlung im Krankheitsfall | F23: =E23*$F$7 -> 0 | I23: =H23*$I$7 -> 0
C24: 2.8 | D24: Sozialversicherung auf Lohnfortzahlung | F24: =E24*$F$7 -> 0 | I24: =H24*$I$7 -> 0
C25: 2.9 | D25: Tarifliche Ausfallzeiten | F25: =E25*$F$7 -> 0 | I25: =H25*$I$7 -> 0
C26: 2.10 | D26: Sozialversicherung auf tarifl. Ausfallzeiten | F26: =E26*$F$7 -> 0 | I26: =H26*$I$7 -> 0
C27: 2.11 | D27: Jahressondervergütungen | F27: =E27*$F$7 -> 0 | I27: =H27*$I$7 -> 0
C28: 2.12 | D28: Sozialversicherung auf Jahressondervergütungen | F28: =E28*$F$7 -> 0 | I28: =H28*$I$7 -> 0
... C31: 2.15 | D31: Sonstige Kosten | F31: =E31*$F$7 -> 0 | I31: =H31*$I$7 -> 0
B32: Summe Position 2 | E32: =SUM(E17:E31) -> 0 | F32: =SUM(F17:F31) -> 0 | H32: =SUM(H17:H31) -> 0 | I32: =SUM(I17:I31) -> 0
B33: 3 | C33: LOHNNEBENKOSTEN
C34: 3.1 | D34: Beiträge zu Berufsorganisationen | F34: =E34*$F$7 -> 0 | I34: =H34*$I$7 -> 0
C35: 3.2 | D35: Schwerbehindertenabgabe | F35: =E35*$F$7 -> 0 | I35: =H35*$I$7 -> 0
B36: SUMME Position 3 | E36: =SUM(E34:E35) -> 0 | F36: =SUM(F34:F35) -> 0 | H36: =SUM(H34:H35) -> 0 | I36: =SUM(I34:I35) -> 0
B37: SUMME Lohn- und Lohngebundene Kosten | E37: =E36+E32+E15 -> 0 | F37: =F36+F32+F15+F7 -> 0 | H37: =H36+H32+H15 -> 0 | I37: =I36+I32+I15+I7 -> 0
B39: 4 | C39: SONSTIGE AUFTRAGSBEZOGENE KOSTEN
C40: 4.1 | D40: Betriebshaftpflicht | F40: =E40*$F$7 -> 0 | I40: =H40*$I$7 -> 0
C41: 4.2 | D41: Sonstige Personalkosten (Overhead) | F41: =E41*$F$7 -> 0 | I41: =H41*$I$7 -> 0
C42: 4.3 | D42: Reinigungsmittel und Kleinmaterial | F42: =E42*$F$7 -> 0 | I42: =H42*$I$7 -> 0
C43: 4.4 | D43: Maschinen- und Gerätekosten (inkl. AfA) | F43: =E43*$F$7 -> 0 | I43: =H43*$I$7 -> 0
C44: 4.5 | D44: Verwaltungskosten (Miete, Telefon usw.) | F44: =E44*$F$7 -> 0 | I44: =H44*$I$7 -> 0
C45: 4.6 | D45: Kosten für Moppwäsche | F45: =E45*$F$7 -> 0 | I45: =H45*$I$7 -> 0
...

Sheet R_Häufigkeit_Faktoren UHR
B2: Turnus | H2: Reinigungshäufigkeit / Monatsfaktor | I2: Reinigungshäufigkeit / Monatsfaktor
D3: Kalendertage | E3: Wochen | F3: Feiertage | H3: Montag - Samstag | I3: Sonntag / Feiertag
B4: 1 | C4: einmal wöchentlich (werktags) | D4: 365 | E4: 52.142857 | F4: 9.7 | G4: =E4 -> 52.142857 | H4: =G4/12 -> 4.3452381
B5: 2 | C5: zweimal wöchentlich (werktags) | D5: 365 | E5: 52.142857 | F5: 9.7 | G5: =E5*2 -> 104.28571 | H5: =G5/12 -> 8.6904762
B6: 2* | C6: zweimal wöchentlich (Samstag / Sonntag) | E6: 52.142857 | F6: 9.7 | G6: =2*52 -> 104 | H6: =4.33 -> 4.33 | I6: 4.33
B7: 3 | C7: dreimal wöchentlich (werktags) | D7: 365 | E7: 52.142857 | F7: 9.7 | G7: =E7*3 -> 156.42857 | H7: =G7/12 -> 13.035714
B8: 5* | C8: fünfmal wöchentlich reinigen (entfällt an Samstagen, Sonn- und Feiertagen) | D8: 365 | E8: 52.142857 | F8: 9.7 | G8: =E8*3 -> 156.42857 | H8: =G8/12 -> 13.035714
B9: 3* | C9: dreimal wöchentlich (2 x Samstag, 1 x Sonntag) | D9: 365 | E9: 52.142857 | F9: 9.7 | G9: =E9*3 -> 156.42857 | H9: =G9/12 -> 13.035714 | I9: 4.33
B10: 4 | C10: viermal wöchentlich werktags) | D10: 365 | E10: 52.142857 | F10: 9.7 | G10: =E10*B10-(F10*(B10/B11)) -> 200.81143 | H10: =G10/12 -> 16.734286
B11: 5 | C11: fünfmal wöchentlich (werktags) | D11: 365 | E11: 52.142857 | F11: 9.7 | G11: =E11*B11-F11 -> 251.01429 | H11: =G11/12 -> 20.917857
B12: 5* | C12: fünfmal wöchentlich reinigen (Feiertage sind nachzuholen) | D12: 365 | E12: 52.142857 | F12: 9.7 | G12: =E12*5 -> 260.71429 | H12: =G12/12 -> 21.72619
B13: 5.5 | C13: fünfmal wöchentlich reinigen, zusätzlich einmal Sichtreinigung (Feiertage sind nachzuholen) | D13: 365 | E13: 52.142857 | F13: 9.7 | G13: =365-52 -> 313 | H13: =G13/12 -> 26.083333
B14: 6 | C14: sechsmal wöchentlich reinigen (entfällt an Sonn- und Feiertagen) | D14: 365 | E14: 52.142857 | F14: 9.7 | G14: =D14-E14-F14 -> 303.15714 | H14: =G14/12 -> 25.263095
B15: 6* | C15: sechsmal wöchentlich reinigen (inkl. Wochenfeiertage) | D15: 365 | E15: 52.142857 | F15: 9.7 | G15: =D15-E15-F15 -> 303.15714 | H15: =G15/12 -> 25.263095 | I15: =F15/12 -> 0.80833333
B16: 7 | C16: siebenmal wöchentlich | D16: 365 | E16: 52.142857 | F16: 9.7 | G16: 365 | H16: =G16/12 -> 30.416667 | I16: =52/12 -> 4.3333333
B17: 10 | C17: zweimal täglich reinigen (entfällt an Samstagen, Sonn- und Feiertagen) | D17: 365 | E17: 52.142857 | F17: 9.7 | G17: =(D17-2*E17-F17)*2 -> 502.02857 | H17: =G17/12 -> 41.835714
B18: 12 | C18: zweimal täglich reinigen (entfällt an Sonn- und Feiertagen) | D18: 365 | E18: 52.142857 | F18: 9.7 | G18: =(D18-E18-F18)*2 -> 606.31429 | H18: =G18/12 -> 50.52619
B19: 13 | C19: zweimal täglich reinigen (Sonntag zweimal Sichtreinigung) | D19: 365 | E19: 52.142857 | F19: 9.7 | G19: =G15*2 -> 606.31429 | H19: =G19/12 -> 50.52619 | I19: =2*52/12/2 -> 4.3333333
B20: M1 | C20: einmal monatlich reinigen (werktags) | D20: 365 | E20: 52.142857 | F20: 9.7 | G20: 12 | H20: =G20/12 -> 1
B21: Q1 | C21: einmal im Quartal reinigen (werktags) | D21: 365 | E21: 52.142857 | F21: 9.7 | G21: 24 | H21: 4
B22: J1 | C22: einmal jährlich reinigen (werktags) | D22: 365 | E22: 52.142857 | F22: 9.7 | G22: 1 | H22: =G22/12 -> 0.083333333
B23: J2 | C23: zweimal jährlich reinigen (werktags) | D23: 365 | E23: 52.142857 | F23: 9.7 | G23: 2 | H23: =G23/12 -> 0.16666667
B24: NB | C24: Nach Bedarf und auf gesonderte Anforderung | D24: 365 | E24: 52.142857 | F24: 9.7 | G24: 2 | H24: =H4 -> 4.3452381

Sheet Raumgruppen_Leistungswerte
B3: Raumgruppe (gem. DIN 13063:2021-09) | D3: Leistungswertspanne | F3: Eingabe Leistungswert des Bieters | G3: variabler Leistungswert m²/h
D4: Min m²/h | E4: Max m²/h | G4: 1 | H4: 2 | I4: 3 | J4: 3.5 | K4: 4 | L4: 5 | M4: 6 | N4: 6.5 | O4: 7 | P4: 10 | Q4: 12 | R4: M2 | S4: M1 | T4: J2 | U4: J1
B5: A1 | C5: Patientenzimmer mit möglichem Infektionsrisiko | D5: 180 | E5: 200 | F5: 200
B6: A2 | C6: Patientenzimmer mit besonderem Infektionsrisiko (Intensiv) | D6: 150 | E6: 180 | F6: 180
B7: A3 | C7: Isolierbereiche | D7: 150 | E7: 180 | F7: 180
B8: B1 | C8: Büroräume (geringe Frequentierung) | D8: 200 | E8: 230
B9: B2 | C9: Büroräume (hohe Frequentierung) | D9: 180 | E9: 210
B10: B3 | C10: Unterrichts- und Schulungsräume | D10: 120 | E10: 160
B11: C | C11: OP-Bereiche (sämtliche Räume hinter den Schleusen) | D11: 25 | E11: 60
B12: D1-1 | C12: Untersuchungs- und Behandlungsräume mit möglichem Infektionsrisiko (z.B. Ambulanzen, Pflegestützpunkte, Entbindung, Radiologie, Dialyse) | D12: 160 | E12: 180
B13: D1-2 | C13: Physikalische Therapie (Bereiche mit möglichem Infektionsrisiko) | D13: 150 | E13: 180
B14: D2 | C14: Untersuchungs- und Behandlungsräume mit besonderem Infektionsrisiko (Eingriffsräume, Endoskopie u.ä.) | D14: 150 | E14: 170
B15: D3 | C15: Aufbereitungseinheit für Medizinprodukte (z.B. AEMP, ZSVA) | D15: 150 | E15: 180
B16: D4-1 | C16: Ver- und Entsorgung— reine Arbeitsräume | D16: 150 | E16: 180
B17: D4-2 | C17: Ver- und Entsorgung— unreine Arbeitsräume | D17: 160 | E17: 190
B18: D5 | C18: Bereiche, in denen vor allem für das Personal ein Infektionsrisiko besteht (Laboratorien, Pathologie) | D18: 160 | E18: 180
B19: E | C19: Sanitärräume (Toilette, Dusche, Bad, Wickelraum) | D19: 50 | E19: 70
... B35: K | C35: Außenbereiche— Gebäudenahe Zugangs- und Aufenthaltsflächen sowie Balkone, Loggien, Dachterrassen | D35: 350 | E35: 400
C37: =Deckblatt!$B$20 -> 0
C39: Datum
